[2021-04-24 11:44:07,730] {taskinstance.py:877} INFO - Dependencies all met for <TaskInstance: project_dag.Stage_songs 2019-02-01T00:00:00+00:00 [queued]>
[2021-04-24 11:44:08,033] {taskinstance.py:877} INFO - Dependencies all met for <TaskInstance: project_dag.Stage_songs 2019-02-01T00:00:00+00:00 [queued]>
[2021-04-24 11:44:08,033] {taskinstance.py:1068} INFO - 
--------------------------------------------------------------------------------
[2021-04-24 11:44:08,033] {taskinstance.py:1069} INFO - Starting attempt 2 of 2
[2021-04-24 11:44:08,033] {taskinstance.py:1070} INFO - 
--------------------------------------------------------------------------------
[2021-04-24 11:44:08,315] {taskinstance.py:1089} INFO - Executing <Task(StageToRedshiftOperator): Stage_songs> on 2019-02-01T00:00:00+00:00
[2021-04-24 11:44:08,363] {standard_task_runner.py:52} INFO - Started process 146 to run task
[2021-04-24 11:44:08,437] {standard_task_runner.py:76} INFO - Running: ['airflow', 'tasks', 'run', 'project_dag', 'Stage_songs', '2019-02-01T00:00:00+00:00', '--job-id', '51', '--pool', 'default_pool', '--raw', '--subdir', 'DAGS_FOLDER/udac_example_dag.py', '--cfg-path', '/tmp/tmpgjhl1rxt', '--error-file', '/tmp/tmpae6ec8ek']
[2021-04-24 11:44:08,447] {standard_task_runner.py:77} INFO - Job 51: Subtask Stage_songs
[2021-04-24 11:44:09,676] {logging_mixin.py:104} INFO - Running <TaskInstance: project_dag.Stage_songs 2019-02-01T00:00:00+00:00 [running]> on host 88dcd2a12842
[2021-04-24 11:44:10,373] {taskinstance.py:1283} INFO - Exporting the following env vars:
AIRFLOW_CTX_DAG_EMAIL=ernest@gmail.com.com
AIRFLOW_CTX_DAG_OWNER=udacity
AIRFLOW_CTX_DAG_ID=project_dag
AIRFLOW_CTX_TASK_ID=Stage_songs
AIRFLOW_CTX_EXECUTION_DATE=2019-02-01T00:00:00+00:00
AIRFLOW_CTX_DAG_RUN_ID=scheduled__2019-02-01T00:00:00+00:00
[2021-04-24 11:44:10,381] {stage_redshift.py:38} INFO - Start implementation of StageToRedshiftOperator
[2021-04-24 11:44:10,525] {taskinstance.py:1482} ERROR - Task failed with exception
Traceback (most recent call last):
  File "/home/airflow/.local/lib/python3.6/site-packages/airflow/models/taskinstance.py", line 1138, in _run_raw_task
    self._prepare_and_execute_task_with_callbacks(context, task)
  File "/home/airflow/.local/lib/python3.6/site-packages/airflow/models/taskinstance.py", line 1311, in _prepare_and_execute_task_with_callbacks
    result = self._execute_task(context, task_copy)
  File "/home/airflow/.local/lib/python3.6/site-packages/airflow/models/taskinstance.py", line 1341, in _execute_task
    result = task_copy.execute(context=context)
  File "/opt/airflow/plugins/operators/stage_redshift.py", line 39, in execute
    aws_hook = AwsHook(self.aws_credentials_id)
  File "/home/airflow/.local/lib/python3.6/site-packages/airflow/contrib/hooks/aws_hook.py", line 41, in __init__
    super().__init__(*args, **kwargs)
  File "/home/airflow/.local/lib/python3.6/site-packages/airflow/providers/amazon/aws/hooks/base_aws.py", line 360, in __init__
    raise AirflowException('Either client_type or resource_type must be provided.')
airflow.exceptions.AirflowException: Either client_type or resource_type must be provided.
[2021-04-24 11:44:10,559] {taskinstance.py:1532} INFO - Marking task as FAILED. dag_id=project_dag, task_id=Stage_songs, execution_date=20190201T000000, start_date=20210424T114407, end_date=20210424T114410
[2021-04-24 11:44:11,329] {configuration.py:352} WARNING - section/key [smtp/smtp_user] not found in config
[2021-04-24 11:44:11,332] {email.py:184} INFO - Email alerting: attempt 1
[2021-04-24 11:44:11,442] {configuration.py:352} WARNING - section/key [smtp/smtp_user] not found in config
[2021-04-24 11:44:11,445] {email.py:184} INFO - Email alerting: attempt 1
[2021-04-24 11:44:11,448] {taskinstance.py:1538} ERROR - Failed to send email to: ['ernest@gmail.com.com']
[2021-04-24 11:44:11,450] {taskinstance.py:1539} ERROR - [Errno 99] Cannot assign requested address
Traceback (most recent call last):
  File "/home/airflow/.local/lib/python3.6/site-packages/airflow/models/taskinstance.py", line 1138, in _run_raw_task
    self._prepare_and_execute_task_with_callbacks(context, task)
  File "/home/airflow/.local/lib/python3.6/site-packages/airflow/models/taskinstance.py", line 1311, in _prepare_and_execute_task_with_callbacks
    result = self._execute_task(context, task_copy)
  File "/home/airflow/.local/lib/python3.6/site-packages/airflow/models/taskinstance.py", line 1341, in _execute_task
    result = task_copy.execute(context=context)
  File "/opt/airflow/plugins/operators/stage_redshift.py", line 39, in execute
    aws_hook = AwsHook(self.aws_credentials_id)
  File "/home/airflow/.local/lib/python3.6/site-packages/airflow/contrib/hooks/aws_hook.py", line 41, in __init__
    super().__init__(*args, **kwargs)
  File "/home/airflow/.local/lib/python3.6/site-packages/airflow/providers/amazon/aws/hooks/base_aws.py", line 360, in __init__
    raise AirflowException('Either client_type or resource_type must be provided.')
airflow.exceptions.AirflowException: Either client_type or resource_type must be provided.

During handling of the above exception, another exception occurred:

Traceback (most recent call last):
  File "/home/airflow/.local/lib/python3.6/site-packages/airflow/models/taskinstance.py", line 1881, in email_alert
    send_email(self.task.email, subject, html_content)
  File "/home/airflow/.local/lib/python3.6/site-packages/airflow/utils/email.py", line 62, in send_email
    **kwargs,
  File "/home/airflow/.local/lib/python3.6/site-packages/airflow/utils/email.py", line 97, in send_email_smtp
    send_mime_email(e_from=smtp_mail_from, e_to=recipients, mime_msg=msg, dryrun=dryrun)
  File "/home/airflow/.local/lib/python3.6/site-packages/airflow/utils/email.py", line 186, in send_mime_email
    conn = _get_smtp_connection(smtp_host, smtp_port, smtp_timeout, smtp_ssl)
  File "/home/airflow/.local/lib/python3.6/site-packages/airflow/utils/email.py", line 220, in _get_smtp_connection
    else smtplib.SMTP(host=host, port=port, timeout=timeout)
  File "/usr/local/lib/python3.6/smtplib.py", line 251, in __init__
    (code, msg) = self.connect(host, port)
  File "/usr/local/lib/python3.6/smtplib.py", line 336, in connect
    self.sock = self._get_socket(host, port, self.timeout)
  File "/usr/local/lib/python3.6/smtplib.py", line 307, in _get_socket
    self.source_address)
  File "/usr/local/lib/python3.6/socket.py", line 724, in create_connection
    raise err
  File "/usr/local/lib/python3.6/socket.py", line 713, in create_connection
    sock.connect(sa)
OSError: [Errno 99] Cannot assign requested address

During handling of the above exception, another exception occurred:

Traceback (most recent call last):
  File "/home/airflow/.local/lib/python3.6/site-packages/airflow/models/taskinstance.py", line 1536, in handle_failure
    self.email_alert(error)
  File "/home/airflow/.local/lib/python3.6/site-packages/airflow/models/taskinstance.py", line 1883, in email_alert
    send_email(self.task.email, subject, html_content_err)
  File "/home/airflow/.local/lib/python3.6/site-packages/airflow/utils/email.py", line 62, in send_email
    **kwargs,
  File "/home/airflow/.local/lib/python3.6/site-packages/airflow/utils/email.py", line 97, in send_email_smtp
    send_mime_email(e_from=smtp_mail_from, e_to=recipients, mime_msg=msg, dryrun=dryrun)
  File "/home/airflow/.local/lib/python3.6/site-packages/airflow/utils/email.py", line 186, in send_mime_email
    conn = _get_smtp_connection(smtp_host, smtp_port, smtp_timeout, smtp_ssl)
  File "/home/airflow/.local/lib/python3.6/site-packages/airflow/utils/email.py", line 220, in _get_smtp_connection
    else smtplib.SMTP(host=host, port=port, timeout=timeout)
  File "/usr/local/lib/python3.6/smtplib.py", line 251, in __init__
    (code, msg) = self.connect(host, port)
  File "/usr/local/lib/python3.6/smtplib.py", line 336, in connect
    self.sock = self._get_socket(host, port, self.timeout)
  File "/usr/local/lib/python3.6/smtplib.py", line 307, in _get_socket
    self.source_address)
  File "/usr/local/lib/python3.6/socket.py", line 724, in create_connection
    raise err
  File "/usr/local/lib/python3.6/socket.py", line 713, in create_connection
    sock.connect(sa)
OSError: [Errno 99] Cannot assign requested address
[2021-04-24 11:44:11,825] {local_task_job.py:146} INFO - Task exited with return code 1
[2021-04-26 09:17:47,086] {taskinstance.py:877} INFO - Dependencies all met for <TaskInstance: project_dag.Stage_songs 2019-02-01T00:00:00+00:00 [queued]>
[2021-04-26 09:17:47,243] {taskinstance.py:877} INFO - Dependencies all met for <TaskInstance: project_dag.Stage_songs 2019-02-01T00:00:00+00:00 [queued]>
[2021-04-26 09:17:47,249] {taskinstance.py:1068} INFO - 
--------------------------------------------------------------------------------
[2021-04-26 09:17:47,250] {taskinstance.py:1069} INFO - Starting attempt 2 of 2
[2021-04-26 09:17:47,252] {taskinstance.py:1070} INFO - 
--------------------------------------------------------------------------------
[2021-04-26 09:17:47,414] {taskinstance.py:1089} INFO - Executing <Task(StageToRedshiftOperator): Stage_songs> on 2019-02-01T00:00:00+00:00
[2021-04-26 09:17:47,547] {standard_task_runner.py:76} INFO - Running: ['airflow', 'tasks', 'run', 'project_dag', 'Stage_songs', '2019-02-01T00:00:00+00:00', '--job-id', '67', '--pool', 'default_pool', '--raw', '--subdir', 'DAGS_FOLDER/udac_example_dag.py', '--cfg-path', '/tmp/tmpqxm9q3dn', '--error-file', '/tmp/tmpcyx91b3o']
[2021-04-26 09:17:47,566] {standard_task_runner.py:77} INFO - Job 67: Subtask Stage_songs
[2021-04-26 09:17:47,517] {standard_task_runner.py:52} INFO - Started process 175 to run task
[2021-04-26 09:17:48,111] {logging_mixin.py:104} INFO - Running <TaskInstance: project_dag.Stage_songs 2019-02-01T00:00:00+00:00 [running]> on host b5c40a6f08c7
[2021-04-26 09:17:48,515] {taskinstance.py:1283} INFO - Exporting the following env vars:
AIRFLOW_CTX_DAG_EMAIL=ernestoffor@gmail.com.com
AIRFLOW_CTX_DAG_OWNER=udacity
AIRFLOW_CTX_DAG_ID=project_dag
AIRFLOW_CTX_TASK_ID=Stage_songs
AIRFLOW_CTX_EXECUTION_DATE=2019-02-01T00:00:00+00:00
AIRFLOW_CTX_DAG_RUN_ID=scheduled__2019-02-01T00:00:00+00:00
[2021-04-26 09:17:48,516] {stage_redshift.py:63} INFO - Start implementation of StageToRedshiftOperator
[2021-04-26 09:17:48,517] {stage_redshift.py:68} INFO - Preparing destination Redshift table
[2021-04-26 09:17:48,613] {base.py:78} INFO - Using connection to: id: redshift. Host: redshift.cxvwoeu3kuea.us-west-2.redshift.amazonaws.com, Port: 5439, Schema: dev, Login: awsuser, Password: XXXXXXXX, extra: None
[2021-04-26 09:17:50,026] {dbapi.py:180} INFO - Running statement: DELETE FROM staging_songs, parameters: None
[2021-04-26 09:17:50,462] {dbapi.py:186} INFO - Rows affected: 0
[2021-04-26 09:17:50,757] {stage_redshift.py:71} INFO - Getting data from S3 to Redshift
[2021-04-26 09:17:50,795] {base.py:78} INFO - Using connection to: id: redshift. Host: redshift.cxvwoeu3kuea.us-west-2.redshift.amazonaws.com, Port: 5439, Schema: dev, Login: awsuser, Password: XXXXXXXX, extra: None
[2021-04-26 09:17:52,247] {dbapi.py:180} INFO - Running statement: 
             COPY staging_songs 
             FROM 's3://udacity-dend/song_data/*/*/*/'
             FORMAT AS JSON 'JSON 'auto''
             CREDENTIALS
             'aws_access_key_id=None;aws_secret_access_key=None'
                , parameters: None
[2021-04-26 09:17:52,646] {taskinstance.py:1482} ERROR - Task failed with exception
Traceback (most recent call last):
  File "/home/airflow/.local/lib/python3.6/site-packages/airflow/models/taskinstance.py", line 1138, in _run_raw_task
    self._prepare_and_execute_task_with_callbacks(context, task)
  File "/home/airflow/.local/lib/python3.6/site-packages/airflow/models/taskinstance.py", line 1311, in _prepare_and_execute_task_with_callbacks
    result = self._execute_task(context, task_copy)
  File "/home/airflow/.local/lib/python3.6/site-packages/airflow/models/taskinstance.py", line 1341, in _execute_task
    result = task_copy.execute(context=context)
  File "/opt/airflow/plugins/operators/stage_redshift.py", line 81, in execute
    redshift.run(execution_sql)
  File "/home/airflow/.local/lib/python3.6/site-packages/airflow/hooks/dbapi.py", line 184, in run
    cur.execute(sql_statement)
psycopg2.errors.SyntaxError: syntax error at or near "auto"
LINE 4:              FORMAT AS JSON 'JSON 'auto''
                                           ^

[2021-04-26 09:17:52,667] {taskinstance.py:1532} INFO - Marking task as FAILED. dag_id=project_dag, task_id=Stage_songs, execution_date=20190201T000000, start_date=20210426T091747, end_date=20210426T091752
[2021-04-26 09:17:53,180] {local_task_job.py:146} INFO - Task exited with return code 1
[2021-04-27 20:42:58,413] {taskinstance.py:877} INFO - Dependencies all met for <TaskInstance: project_dag.Stage_songs 2019-02-01T00:00:00+00:00 [queued]>
[2021-04-27 20:42:58,601] {taskinstance.py:877} INFO - Dependencies all met for <TaskInstance: project_dag.Stage_songs 2019-02-01T00:00:00+00:00 [queued]>
[2021-04-27 20:42:58,606] {taskinstance.py:1068} INFO - 
--------------------------------------------------------------------------------
[2021-04-27 20:42:58,606] {taskinstance.py:1069} INFO - Starting attempt 2 of 2
[2021-04-27 20:42:58,607] {taskinstance.py:1070} INFO - 
--------------------------------------------------------------------------------
[2021-04-27 20:42:58,655] {taskinstance.py:1089} INFO - Executing <Task(StageToRedshiftOperator): Stage_songs> on 2019-02-01T00:00:00+00:00
[2021-04-27 20:42:58,678] {standard_task_runner.py:76} INFO - Running: ['airflow', 'tasks', 'run', 'project_dag', 'Stage_songs', '2019-02-01T00:00:00+00:00', '--job-id', '115', '--pool', 'default_pool', '--raw', '--subdir', 'DAGS_FOLDER/udac_example_dag.py', '--cfg-path', '/tmp/tmphqg6dc8t', '--error-file', '/tmp/tmp8e9szyxo']
[2021-04-27 20:42:58,679] {standard_task_runner.py:77} INFO - Job 115: Subtask Stage_songs
[2021-04-27 20:42:58,667] {standard_task_runner.py:52} INFO - Started process 264 to run task
[2021-04-27 20:42:58,796] {logging_mixin.py:104} INFO - Running <TaskInstance: project_dag.Stage_songs 2019-02-01T00:00:00+00:00 [running]> on host 478c7ec349b0
[2021-04-27 20:42:58,903] {taskinstance.py:1283} INFO - Exporting the following env vars:
AIRFLOW_CTX_DAG_EMAIL=ernestoffor@gmail.com.com
AIRFLOW_CTX_DAG_OWNER=udacity
AIRFLOW_CTX_DAG_ID=project_dag
AIRFLOW_CTX_TASK_ID=Stage_songs
AIRFLOW_CTX_EXECUTION_DATE=2019-02-01T00:00:00+00:00
AIRFLOW_CTX_DAG_RUN_ID=scheduled__2019-02-01T00:00:00+00:00
[2021-04-27 20:42:58,905] {stage_redshift.py:67} INFO - Start implementation of StageToRedshiftOperator
[2021-04-27 20:42:58,907] {stage_redshift.py:74} INFO - Preparing destination Redshift table
[2021-04-27 20:42:58,934] {base.py:78} INFO - Using connection to: id: redshift. Host: redshift.cxvwoeu3kuea.us-west-2.redshift.amazonaws.com, Port: 5439, Schema: dev, Login: awsuser, Password: XXXXXXXX, extra: None
[2021-04-27 20:43:00,392] {dbapi.py:180} INFO - Running statement: DELETE FROM staging_songs, parameters: None
[2021-04-27 20:43:00,837] {dbapi.py:186} INFO - Rows affected: 0
[2021-04-27 20:43:01,129] {stage_redshift.py:77} INFO - Getting data from S3 to Redshift
[2021-04-27 20:43:03,243] {taskinstance.py:1482} ERROR - Task failed with exception
Traceback (most recent call last):
  File "/home/airflow/.local/lib/python3.6/site-packages/airflow/models/taskinstance.py", line 1138, in _run_raw_task
    self._prepare_and_execute_task_with_callbacks(context, task)
  File "/home/airflow/.local/lib/python3.6/site-packages/airflow/models/taskinstance.py", line 1311, in _prepare_and_execute_task_with_callbacks
    result = self._execute_task(context, task_copy)
  File "/home/airflow/.local/lib/python3.6/site-packages/airflow/models/taskinstance.py", line 1341, in _execute_task
    result = task_copy.execute(context=context)
  File "/opt/airflow/plugins/operators/stage_redshift.py", line 83, in execute
    s3.get_credentials().access_key,
  File "/home/airflow/.local/lib/python3.6/site-packages/airflow/providers/amazon/aws/hooks/base_aws.py", line 478, in get_credentials
    return session.get_credentials().get_frozen_credentials()
AttributeError: 'NoneType' object has no attribute 'get_frozen_credentials'
[2021-04-27 20:43:03,247] {taskinstance.py:1532} INFO - Marking task as FAILED. dag_id=project_dag, task_id=Stage_songs, execution_date=20190201T000000, start_date=20210427T204258, end_date=20210427T204303
[2021-04-27 20:43:03,400] {local_task_job.py:146} INFO - Task exited with return code 1
