[2021-04-24 11:51:11,791] {taskinstance.py:877} INFO - Dependencies all met for <TaskInstance: project_dag.Stage_songs 2021-02-01T00:00:00+00:00 [queued]>
[2021-04-24 11:51:11,931] {taskinstance.py:877} INFO - Dependencies all met for <TaskInstance: project_dag.Stage_songs 2021-02-01T00:00:00+00:00 [queued]>
[2021-04-24 11:51:11,931] {taskinstance.py:1068} INFO - 
--------------------------------------------------------------------------------
[2021-04-24 11:51:11,931] {taskinstance.py:1069} INFO - Starting attempt 2 of 2
[2021-04-24 11:51:11,931] {taskinstance.py:1070} INFO - 
--------------------------------------------------------------------------------
[2021-04-24 11:51:12,133] {taskinstance.py:1089} INFO - Executing <Task(StageToRedshiftOperator): Stage_songs> on 2021-02-01T00:00:00+00:00
[2021-04-24 11:51:12,160] {standard_task_runner.py:52} INFO - Started process 291 to run task
[2021-04-24 11:51:12,258] {standard_task_runner.py:76} INFO - Running: ['airflow', 'tasks', 'run', 'project_dag', 'Stage_songs', '2021-02-01T00:00:00+00:00', '--job-id', '126', '--pool', 'default_pool', '--raw', '--subdir', 'DAGS_FOLDER/udac_example_dag.py', '--cfg-path', '/tmp/tmpoioh2p4b', '--error-file', '/tmp/tmpdd_chbsy']
[2021-04-24 11:51:12,258] {standard_task_runner.py:77} INFO - Job 126: Subtask Stage_songs
[2021-04-24 11:51:12,972] {logging_mixin.py:104} INFO - Running <TaskInstance: project_dag.Stage_songs 2021-02-01T00:00:00+00:00 [running]> on host 88dcd2a12842
[2021-04-24 11:51:13,401] {taskinstance.py:1283} INFO - Exporting the following env vars:
AIRFLOW_CTX_DAG_EMAIL=ernest@gmail.com.com
AIRFLOW_CTX_DAG_OWNER=udacity
AIRFLOW_CTX_DAG_ID=project_dag
AIRFLOW_CTX_TASK_ID=Stage_songs
AIRFLOW_CTX_EXECUTION_DATE=2021-02-01T00:00:00+00:00
AIRFLOW_CTX_DAG_RUN_ID=scheduled__2021-02-01T00:00:00+00:00
[2021-04-24 11:51:13,412] {stage_redshift.py:38} INFO - Start implementation of StageToRedshiftOperator
[2021-04-24 11:51:13,463] {taskinstance.py:1482} ERROR - Task failed with exception
Traceback (most recent call last):
  File "/home/airflow/.local/lib/python3.6/site-packages/airflow/models/taskinstance.py", line 1138, in _run_raw_task
    self._prepare_and_execute_task_with_callbacks(context, task)
  File "/home/airflow/.local/lib/python3.6/site-packages/airflow/models/taskinstance.py", line 1311, in _prepare_and_execute_task_with_callbacks
    result = self._execute_task(context, task_copy)
  File "/home/airflow/.local/lib/python3.6/site-packages/airflow/models/taskinstance.py", line 1341, in _execute_task
    result = task_copy.execute(context=context)
  File "/opt/airflow/plugins/operators/stage_redshift.py", line 39, in execute
    aws_hook = AwsHook(self.aws_credentials_id)
  File "/home/airflow/.local/lib/python3.6/site-packages/airflow/contrib/hooks/aws_hook.py", line 41, in __init__
    super().__init__(*args, **kwargs)
  File "/home/airflow/.local/lib/python3.6/site-packages/airflow/providers/amazon/aws/hooks/base_aws.py", line 360, in __init__
    raise AirflowException('Either client_type or resource_type must be provided.')
airflow.exceptions.AirflowException: Either client_type or resource_type must be provided.
[2021-04-24 11:51:13,468] {taskinstance.py:1532} INFO - Marking task as FAILED. dag_id=project_dag, task_id=Stage_songs, execution_date=20210201T000000, start_date=20210424T115111, end_date=20210424T115113
[2021-04-24 11:51:13,595] {configuration.py:352} WARNING - section/key [smtp/smtp_user] not found in config
[2021-04-24 11:51:13,623] {email.py:184} INFO - Email alerting: attempt 1
[2021-04-24 11:51:13,640] {configuration.py:352} WARNING - section/key [smtp/smtp_user] not found in config
[2021-04-24 11:51:13,660] {email.py:184} INFO - Email alerting: attempt 1
[2021-04-24 11:51:13,665] {taskinstance.py:1538} ERROR - Failed to send email to: ['ernest@gmail.com.com']
[2021-04-24 11:51:13,667] {taskinstance.py:1539} ERROR - [Errno 99] Cannot assign requested address
Traceback (most recent call last):
  File "/home/airflow/.local/lib/python3.6/site-packages/airflow/models/taskinstance.py", line 1138, in _run_raw_task
    self._prepare_and_execute_task_with_callbacks(context, task)
  File "/home/airflow/.local/lib/python3.6/site-packages/airflow/models/taskinstance.py", line 1311, in _prepare_and_execute_task_with_callbacks
    result = self._execute_task(context, task_copy)
  File "/home/airflow/.local/lib/python3.6/site-packages/airflow/models/taskinstance.py", line 1341, in _execute_task
    result = task_copy.execute(context=context)
  File "/opt/airflow/plugins/operators/stage_redshift.py", line 39, in execute
    aws_hook = AwsHook(self.aws_credentials_id)
  File "/home/airflow/.local/lib/python3.6/site-packages/airflow/contrib/hooks/aws_hook.py", line 41, in __init__
    super().__init__(*args, **kwargs)
  File "/home/airflow/.local/lib/python3.6/site-packages/airflow/providers/amazon/aws/hooks/base_aws.py", line 360, in __init__
    raise AirflowException('Either client_type or resource_type must be provided.')
airflow.exceptions.AirflowException: Either client_type or resource_type must be provided.

During handling of the above exception, another exception occurred:

Traceback (most recent call last):
  File "/home/airflow/.local/lib/python3.6/site-packages/airflow/models/taskinstance.py", line 1881, in email_alert
    send_email(self.task.email, subject, html_content)
  File "/home/airflow/.local/lib/python3.6/site-packages/airflow/utils/email.py", line 62, in send_email
    **kwargs,
  File "/home/airflow/.local/lib/python3.6/site-packages/airflow/utils/email.py", line 97, in send_email_smtp
    send_mime_email(e_from=smtp_mail_from, e_to=recipients, mime_msg=msg, dryrun=dryrun)
  File "/home/airflow/.local/lib/python3.6/site-packages/airflow/utils/email.py", line 186, in send_mime_email
    conn = _get_smtp_connection(smtp_host, smtp_port, smtp_timeout, smtp_ssl)
  File "/home/airflow/.local/lib/python3.6/site-packages/airflow/utils/email.py", line 220, in _get_smtp_connection
    else smtplib.SMTP(host=host, port=port, timeout=timeout)
  File "/usr/local/lib/python3.6/smtplib.py", line 251, in __init__
    (code, msg) = self.connect(host, port)
  File "/usr/local/lib/python3.6/smtplib.py", line 336, in connect
    self.sock = self._get_socket(host, port, self.timeout)
  File "/usr/local/lib/python3.6/smtplib.py", line 307, in _get_socket
    self.source_address)
  File "/usr/local/lib/python3.6/socket.py", line 724, in create_connection
    raise err
  File "/usr/local/lib/python3.6/socket.py", line 713, in create_connection
    sock.connect(sa)
OSError: [Errno 99] Cannot assign requested address

During handling of the above exception, another exception occurred:

Traceback (most recent call last):
  File "/home/airflow/.local/lib/python3.6/site-packages/airflow/models/taskinstance.py", line 1536, in handle_failure
    self.email_alert(error)
  File "/home/airflow/.local/lib/python3.6/site-packages/airflow/models/taskinstance.py", line 1883, in email_alert
    send_email(self.task.email, subject, html_content_err)
  File "/home/airflow/.local/lib/python3.6/site-packages/airflow/utils/email.py", line 62, in send_email
    **kwargs,
  File "/home/airflow/.local/lib/python3.6/site-packages/airflow/utils/email.py", line 97, in send_email_smtp
    send_mime_email(e_from=smtp_mail_from, e_to=recipients, mime_msg=msg, dryrun=dryrun)
  File "/home/airflow/.local/lib/python3.6/site-packages/airflow/utils/email.py", line 186, in send_mime_email
    conn = _get_smtp_connection(smtp_host, smtp_port, smtp_timeout, smtp_ssl)
  File "/home/airflow/.local/lib/python3.6/site-packages/airflow/utils/email.py", line 220, in _get_smtp_connection
    else smtplib.SMTP(host=host, port=port, timeout=timeout)
  File "/usr/local/lib/python3.6/smtplib.py", line 251, in __init__
    (code, msg) = self.connect(host, port)
  File "/usr/local/lib/python3.6/smtplib.py", line 336, in connect
    self.sock = self._get_socket(host, port, self.timeout)
  File "/usr/local/lib/python3.6/smtplib.py", line 307, in _get_socket
    self.source_address)
  File "/usr/local/lib/python3.6/socket.py", line 724, in create_connection
    raise err
  File "/usr/local/lib/python3.6/socket.py", line 713, in create_connection
    sock.connect(sa)
OSError: [Errno 99] Cannot assign requested address
[2021-04-24 11:51:13,852] {local_task_job.py:146} INFO - Task exited with return code 1
[2021-04-26 09:14:02,800] {taskinstance.py:877} INFO - Dependencies all met for <TaskInstance: project_dag.Stage_songs 2021-02-01T00:00:00+00:00 [queued]>
[2021-04-26 09:14:03,307] {taskinstance.py:877} INFO - Dependencies all met for <TaskInstance: project_dag.Stage_songs 2021-02-01T00:00:00+00:00 [queued]>
[2021-04-26 09:14:03,311] {taskinstance.py:1068} INFO - 
--------------------------------------------------------------------------------
[2021-04-26 09:14:03,326] {taskinstance.py:1069} INFO - Starting attempt 2 of 2
[2021-04-26 09:14:03,328] {taskinstance.py:1070} INFO - 
--------------------------------------------------------------------------------
[2021-04-26 09:14:03,668] {taskinstance.py:1089} INFO - Executing <Task(StageToRedshiftOperator): Stage_songs> on 2021-02-01T00:00:00+00:00
[2021-04-26 09:14:03,817] {standard_task_runner.py:76} INFO - Running: ['airflow', 'tasks', 'run', 'project_dag', 'Stage_songs', '2021-02-01T00:00:00+00:00', '--job-id', '57', '--pool', 'default_pool', '--raw', '--subdir', 'DAGS_FOLDER/udac_example_dag.py', '--cfg-path', '/tmp/tmpdxs1wsec', '--error-file', '/tmp/tmp90us2rh_']
[2021-04-26 09:14:03,820] {standard_task_runner.py:77} INFO - Job 57: Subtask Stage_songs
[2021-04-26 09:14:03,750] {standard_task_runner.py:52} INFO - Started process 163 to run task
[2021-04-26 09:14:04,447] {logging_mixin.py:104} INFO - Running <TaskInstance: project_dag.Stage_songs 2021-02-01T00:00:00+00:00 [running]> on host b5c40a6f08c7
[2021-04-26 09:14:05,131] {taskinstance.py:1283} INFO - Exporting the following env vars:
AIRFLOW_CTX_DAG_EMAIL=ernestoffor@gmail.com.com
AIRFLOW_CTX_DAG_OWNER=udacity
AIRFLOW_CTX_DAG_ID=project_dag
AIRFLOW_CTX_TASK_ID=Stage_songs
AIRFLOW_CTX_EXECUTION_DATE=2021-02-01T00:00:00+00:00
AIRFLOW_CTX_DAG_RUN_ID=scheduled__2021-02-01T00:00:00+00:00
[2021-04-26 09:14:05,145] {stage_redshift.py:63} INFO - Start implementation of StageToRedshiftOperator
[2021-04-26 09:14:05,167] {stage_redshift.py:68} INFO - Preparing destination Redshift table
[2021-04-26 09:14:05,264] {base.py:78} INFO - Using connection to: id: redshift. Host: redshift.cxvwoeu3kuea.us-west-2.redshift.amazonaws.com, Port: 5439, Schema: dev, Login: awsuser, Password: XXXXXXXX, extra: None
[2021-04-26 09:14:06,827] {dbapi.py:180} INFO - Running statement: DELETE FROM staging_songs, parameters: None
[2021-04-26 09:14:07,276] {dbapi.py:186} INFO - Rows affected: 0
[2021-04-26 09:14:07,656] {stage_redshift.py:71} INFO - Getting data from S3 to Redshift
[2021-04-26 09:14:07,918] {base.py:78} INFO - Using connection to: id: redshift. Host: redshift.cxvwoeu3kuea.us-west-2.redshift.amazonaws.com, Port: 5439, Schema: dev, Login: awsuser, Password: XXXXXXXX, extra: None
[2021-04-26 09:14:09,378] {dbapi.py:180} INFO - Running statement: 
             COPY staging_songs 
             FROM 's3://udacity-dend/song_data/*/*/*/'
             FORMAT AS JSON 'JSON 'auto''
             CREDENTIALS
             'aws_access_key_id=None;aws_secret_access_key=None'
                , parameters: None
[2021-04-26 09:14:09,785] {taskinstance.py:1482} ERROR - Task failed with exception
Traceback (most recent call last):
  File "/home/airflow/.local/lib/python3.6/site-packages/airflow/models/taskinstance.py", line 1138, in _run_raw_task
    self._prepare_and_execute_task_with_callbacks(context, task)
  File "/home/airflow/.local/lib/python3.6/site-packages/airflow/models/taskinstance.py", line 1311, in _prepare_and_execute_task_with_callbacks
    result = self._execute_task(context, task_copy)
  File "/home/airflow/.local/lib/python3.6/site-packages/airflow/models/taskinstance.py", line 1341, in _execute_task
    result = task_copy.execute(context=context)
  File "/opt/airflow/plugins/operators/stage_redshift.py", line 81, in execute
    redshift.run(execution_sql)
  File "/home/airflow/.local/lib/python3.6/site-packages/airflow/hooks/dbapi.py", line 184, in run
    cur.execute(sql_statement)
psycopg2.errors.SyntaxError: syntax error at or near "auto"
LINE 4:              FORMAT AS JSON 'JSON 'auto''
                                           ^

[2021-04-26 09:14:09,833] {taskinstance.py:1532} INFO - Marking task as FAILED. dag_id=project_dag, task_id=Stage_songs, execution_date=20210201T000000, start_date=20210426T091402, end_date=20210426T091409
[2021-04-26 09:14:10,394] {local_task_job.py:146} INFO - Task exited with return code 1
[2021-04-26 12:41:48,506] {taskinstance.py:877} INFO - Dependencies all met for <TaskInstance: project_dag.Stage_songs 2021-02-01T00:00:00+00:00 [queued]>
[2021-04-26 12:41:49,334] {taskinstance.py:877} INFO - Dependencies all met for <TaskInstance: project_dag.Stage_songs 2021-02-01T00:00:00+00:00 [queued]>
[2021-04-26 12:41:49,334] {taskinstance.py:1068} INFO - 
--------------------------------------------------------------------------------
[2021-04-26 12:41:49,334] {taskinstance.py:1069} INFO - Starting attempt 2 of 2
[2021-04-26 12:41:49,334] {taskinstance.py:1070} INFO - 
--------------------------------------------------------------------------------
[2021-04-26 12:41:49,926] {taskinstance.py:1089} INFO - Executing <Task(StageToRedshiftOperator): Stage_songs> on 2021-02-01T00:00:00+00:00
[2021-04-26 12:41:50,110] {standard_task_runner.py:76} INFO - Running: ['airflow', 'tasks', 'run', 'project_dag', 'Stage_songs', '2021-02-01T00:00:00+00:00', '--job-id', '48', '--pool', 'default_pool', '--raw', '--subdir', 'DAGS_FOLDER/udac_example_dag.py', '--cfg-path', '/tmp/tmpm8j5v_fk', '--error-file', '/tmp/tmpe48w4552']
[2021-04-26 12:41:50,136] {standard_task_runner.py:77} INFO - Job 48: Subtask Stage_songs
[2021-04-26 12:41:50,059] {standard_task_runner.py:52} INFO - Started process 158 to run task
[2021-04-26 12:41:51,655] {logging_mixin.py:104} INFO - Running <TaskInstance: project_dag.Stage_songs 2021-02-01T00:00:00+00:00 [running]> on host 0f1e1da1f4f6
[2021-04-26 12:41:52,655] {taskinstance.py:1283} INFO - Exporting the following env vars:
AIRFLOW_CTX_DAG_EMAIL=ernestoffor@gmail.com.com
AIRFLOW_CTX_DAG_OWNER=udacity
AIRFLOW_CTX_DAG_ID=project_dag
AIRFLOW_CTX_TASK_ID=Stage_songs
AIRFLOW_CTX_EXECUTION_DATE=2021-02-01T00:00:00+00:00
AIRFLOW_CTX_DAG_RUN_ID=scheduled__2021-02-01T00:00:00+00:00
[2021-04-26 12:41:52,656] {stage_redshift.py:62} INFO - Start implementation of StageToRedshiftOperator
[2021-04-26 12:41:52,657] {stage_redshift.py:67} INFO - Preparing destination Redshift table
[2021-04-26 12:41:52,825] {base.py:78} INFO - Using connection to: id: redshift. Host: redshift.cxvwoeu3kuea.us-west-2.redshift.amazonaws.com, Port: 5439, Schema: dev, Login: awsuser, Password: XXXXXXXX, extra: None
[2021-04-26 12:41:52,893] {taskinstance.py:1482} ERROR - Task failed with exception
Traceback (most recent call last):
  File "/home/airflow/.local/lib/python3.6/site-packages/airflow/models/taskinstance.py", line 1138, in _run_raw_task
    self._prepare_and_execute_task_with_callbacks(context, task)
  File "/home/airflow/.local/lib/python3.6/site-packages/airflow/models/taskinstance.py", line 1311, in _prepare_and_execute_task_with_callbacks
    result = self._execute_task(context, task_copy)
  File "/home/airflow/.local/lib/python3.6/site-packages/airflow/models/taskinstance.py", line 1341, in _execute_task
    result = task_copy.execute(context=context)
  File "/opt/airflow/plugins/operators/stage_redshift.py", line 68, in execute
    redshift.run("DELETE FROM {}".format(self.staging_table))
  File "/home/airflow/.local/lib/python3.6/site-packages/airflow/hooks/dbapi.py", line 173, in run
    with closing(self.get_conn()) as conn:
  File "/home/airflow/.local/lib/python3.6/site-packages/airflow/providers/postgres/hooks/postgres.py", line 108, in get_conn
    self.conn = psycopg2.connect(**conn_args)
  File "/home/airflow/.local/lib/python3.6/site-packages/psycopg2/__init__.py", line 127, in connect
    conn = _connect(dsn, connection_factory=connection_factory, **kwasync)
psycopg2.OperationalError: could not translate host name "redshift.cxvwoeu3kuea.us-west-2.redshift.amazonaws.com" to address: Name or service not known

[2021-04-26 12:41:52,931] {taskinstance.py:1532} INFO - Marking task as FAILED. dag_id=project_dag, task_id=Stage_songs, execution_date=20210201T000000, start_date=20210426T124148, end_date=20210426T124152
[2021-04-26 12:41:53,580] {local_task_job.py:146} INFO - Task exited with return code 1
[2021-04-27 19:26:52,765] {taskinstance.py:877} INFO - Dependencies all met for <TaskInstance: project_dag.Stage_songs 2021-02-01T00:00:00+00:00 [queued]>
[2021-04-27 19:26:52,928] {taskinstance.py:877} INFO - Dependencies all met for <TaskInstance: project_dag.Stage_songs 2021-02-01T00:00:00+00:00 [queued]>
[2021-04-27 19:26:52,928] {taskinstance.py:1068} INFO - 
--------------------------------------------------------------------------------
[2021-04-27 19:26:52,929] {taskinstance.py:1069} INFO - Starting attempt 2 of 2
[2021-04-27 19:26:52,929] {taskinstance.py:1070} INFO - 
--------------------------------------------------------------------------------
[2021-04-27 19:26:53,295] {taskinstance.py:1089} INFO - Executing <Task(StageToRedshiftOperator): Stage_songs> on 2021-02-01T00:00:00+00:00
[2021-04-27 19:26:53,388] {standard_task_runner.py:52} INFO - Started process 96 to run task
[2021-04-27 19:26:53,435] {standard_task_runner.py:76} INFO - Running: ['airflow', 'tasks', 'run', 'project_dag', 'Stage_songs', '2021-02-01T00:00:00+00:00', '--job-id', '83', '--pool', 'default_pool', '--raw', '--subdir', 'DAGS_FOLDER/udac_example_dag.py', '--cfg-path', '/tmp/tmpkv950sz9', '--error-file', '/tmp/tmpl6273bej']
[2021-04-27 19:26:53,459] {standard_task_runner.py:77} INFO - Job 83: Subtask Stage_songs
[2021-04-27 19:26:53,869] {logging_mixin.py:104} INFO - Running <TaskInstance: project_dag.Stage_songs 2021-02-01T00:00:00+00:00 [running]> on host 0f1e1da1f4f6
[2021-04-27 19:26:54,200] {taskinstance.py:1283} INFO - Exporting the following env vars:
AIRFLOW_CTX_DAG_EMAIL=ernestoffor@gmail.com.com
AIRFLOW_CTX_DAG_OWNER=udacity
AIRFLOW_CTX_DAG_ID=project_dag
AIRFLOW_CTX_TASK_ID=Stage_songs
AIRFLOW_CTX_EXECUTION_DATE=2021-02-01T00:00:00+00:00
AIRFLOW_CTX_DAG_RUN_ID=scheduled__2021-02-01T00:00:00+00:00
[2021-04-27 19:26:54,201] {stage_redshift.py:65} INFO - Start implementation of StageToRedshiftOperator
[2021-04-27 19:26:54,201] {taskinstance.py:1482} ERROR - Task failed with exception
Traceback (most recent call last):
  File "/home/airflow/.local/lib/python3.6/site-packages/airflow/models/taskinstance.py", line 1138, in _run_raw_task
    self._prepare_and_execute_task_with_callbacks(context, task)
  File "/home/airflow/.local/lib/python3.6/site-packages/airflow/models/taskinstance.py", line 1311, in _prepare_and_execute_task_with_callbacks
    result = self._execute_task(context, task_copy)
  File "/home/airflow/.local/lib/python3.6/site-packages/airflow/models/taskinstance.py", line 1341, in _execute_task
    result = task_copy.execute(context=context)
  File "/opt/airflow/plugins/operators/stage_redshift.py", line 66, in execute
    s3 = S3hook(aws_conn_id=self.aws_credentials_id)
NameError: name 'S3hook' is not defined
[2021-04-27 19:26:54,206] {taskinstance.py:1532} INFO - Marking task as FAILED. dag_id=project_dag, task_id=Stage_songs, execution_date=20210201T000000, start_date=20210427T192652, end_date=20210427T192654
[2021-04-27 19:26:54,631] {local_task_job.py:146} INFO - Task exited with return code 1
