[2021-04-24 11:40:02,883] {taskinstance.py:877} INFO - Dependencies all met for <TaskInstance: project_dag.Stage_events 2020-05-01T00:00:00+00:00 [queued]>
[2021-04-24 11:40:03,067] {taskinstance.py:877} INFO - Dependencies all met for <TaskInstance: project_dag.Stage_events 2020-05-01T00:00:00+00:00 [queued]>
[2021-04-24 11:40:03,067] {taskinstance.py:1068} INFO - 
--------------------------------------------------------------------------------
[2021-04-24 11:40:03,068] {taskinstance.py:1069} INFO - Starting attempt 1 of 2
[2021-04-24 11:40:03,068] {taskinstance.py:1070} INFO - 
--------------------------------------------------------------------------------
[2021-04-24 11:40:03,208] {taskinstance.py:1089} INFO - Executing <Task(StageToRedshiftOperator): Stage_events> on 2020-05-01T00:00:00+00:00
[2021-04-24 11:40:03,276] {standard_task_runner.py:52} INFO - Started process 131 to run task
[2021-04-24 11:40:03,300] {standard_task_runner.py:76} INFO - Running: ['airflow', 'tasks', 'run', 'project_dag', 'Stage_events', '2020-05-01T00:00:00+00:00', '--job-id', '45', '--pool', 'default_pool', '--raw', '--subdir', 'DAGS_FOLDER/udac_example_dag.py', '--cfg-path', '/tmp/tmp1qlpq1k_', '--error-file', '/tmp/tmp6w13ofje']
[2021-04-24 11:40:03,310] {standard_task_runner.py:77} INFO - Job 45: Subtask Stage_events
[2021-04-24 11:40:04,138] {logging_mixin.py:104} INFO - Running <TaskInstance: project_dag.Stage_events 2020-05-01T00:00:00+00:00 [running]> on host 88dcd2a12842
[2021-04-24 11:40:04,835] {taskinstance.py:1283} INFO - Exporting the following env vars:
AIRFLOW_CTX_DAG_EMAIL=ernest@gmail.com.com
AIRFLOW_CTX_DAG_OWNER=udacity
AIRFLOW_CTX_DAG_ID=project_dag
AIRFLOW_CTX_TASK_ID=Stage_events
AIRFLOW_CTX_EXECUTION_DATE=2020-05-01T00:00:00+00:00
AIRFLOW_CTX_DAG_RUN_ID=scheduled__2020-05-01T00:00:00+00:00
[2021-04-24 11:40:04,839] {stage_redshift.py:38} INFO - Start implementation of StageToRedshiftOperator
[2021-04-24 11:40:04,899] {taskinstance.py:1482} ERROR - Task failed with exception
Traceback (most recent call last):
  File "/home/airflow/.local/lib/python3.6/site-packages/airflow/models/taskinstance.py", line 1138, in _run_raw_task
    self._prepare_and_execute_task_with_callbacks(context, task)
  File "/home/airflow/.local/lib/python3.6/site-packages/airflow/models/taskinstance.py", line 1311, in _prepare_and_execute_task_with_callbacks
    result = self._execute_task(context, task_copy)
  File "/home/airflow/.local/lib/python3.6/site-packages/airflow/models/taskinstance.py", line 1341, in _execute_task
    result = task_copy.execute(context=context)
  File "/opt/airflow/plugins/operators/stage_redshift.py", line 39, in execute
    aws_hook = AwsHook(self.aws_credentials_id)
  File "/home/airflow/.local/lib/python3.6/site-packages/airflow/contrib/hooks/aws_hook.py", line 41, in __init__
    super().__init__(*args, **kwargs)
  File "/home/airflow/.local/lib/python3.6/site-packages/airflow/providers/amazon/aws/hooks/base_aws.py", line 360, in __init__
    raise AirflowException('Either client_type or resource_type must be provided.')
airflow.exceptions.AirflowException: Either client_type or resource_type must be provided.
[2021-04-24 11:40:04,935] {taskinstance.py:1532} INFO - Marking task as UP_FOR_RETRY. dag_id=project_dag, task_id=Stage_events, execution_date=20200501T000000, start_date=20210424T114002, end_date=20210424T114004
[2021-04-24 11:40:05,165] {local_task_job.py:146} INFO - Task exited with return code 1
[2021-04-26 12:34:45,865] {taskinstance.py:877} INFO - Dependencies all met for <TaskInstance: project_dag.Stage_events 2020-05-01T00:00:00+00:00 [queued]>
[2021-04-26 12:34:46,258] {taskinstance.py:877} INFO - Dependencies all met for <TaskInstance: project_dag.Stage_events 2020-05-01T00:00:00+00:00 [queued]>
[2021-04-26 12:34:46,258] {taskinstance.py:1068} INFO - 
--------------------------------------------------------------------------------
[2021-04-26 12:34:46,258] {taskinstance.py:1069} INFO - Starting attempt 1 of 2
[2021-04-26 12:34:46,258] {taskinstance.py:1070} INFO - 
--------------------------------------------------------------------------------
[2021-04-26 12:34:46,452] {taskinstance.py:1089} INFO - Executing <Task(StageToRedshiftOperator): Stage_events> on 2020-05-01T00:00:00+00:00
[2021-04-26 12:34:46,475] {standard_task_runner.py:52} INFO - Started process 61 to run task
[2021-04-26 12:34:46,510] {standard_task_runner.py:76} INFO - Running: ['airflow', 'tasks', 'run', 'project_dag', 'Stage_events', '2020-05-01T00:00:00+00:00', '--job-id', '5', '--pool', 'default_pool', '--raw', '--subdir', 'DAGS_FOLDER/udac_example_dag.py', '--cfg-path', '/tmp/tmp45nn_jxk', '--error-file', '/tmp/tmpsg2sw6j6']
[2021-04-26 12:34:46,510] {standard_task_runner.py:77} INFO - Job 5: Subtask Stage_events
[2021-04-26 12:34:47,017] {logging_mixin.py:104} INFO - Running <TaskInstance: project_dag.Stage_events 2020-05-01T00:00:00+00:00 [running]> on host 0f1e1da1f4f6
[2021-04-26 12:34:47,431] {taskinstance.py:1283} INFO - Exporting the following env vars:
AIRFLOW_CTX_DAG_EMAIL=ernestoffor@gmail.com.com
AIRFLOW_CTX_DAG_OWNER=udacity
AIRFLOW_CTX_DAG_ID=project_dag
AIRFLOW_CTX_TASK_ID=Stage_events
AIRFLOW_CTX_EXECUTION_DATE=2020-05-01T00:00:00+00:00
AIRFLOW_CTX_DAG_RUN_ID=scheduled__2020-05-01T00:00:00+00:00
[2021-04-26 12:34:47,432] {stage_redshift.py:62} INFO - Start implementation of StageToRedshiftOperator
[2021-04-26 12:34:47,432] {stage_redshift.py:67} INFO - Preparing destination Redshift table
[2021-04-26 12:34:47,522] {base.py:78} INFO - Using connection to: id: redshift. Host: redshift.cxvwoeu3kuea.us-west-2.redshift.amazonaws.com, Port: 5439, Schema: dev, Login: awsuser, Password: XXXXXXXX, extra: None
[2021-04-26 12:34:49,085] {dbapi.py:180} INFO - Running statement: DELETE FROM staging_events, parameters: None
[2021-04-26 12:34:49,850] {dbapi.py:186} INFO - Rows affected: 0
[2021-04-26 12:34:50,284] {stage_redshift.py:70} INFO - Getting data from S3 to Redshift
[2021-04-26 12:34:50,317] {base.py:78} INFO - Using connection to: id: redshift. Host: redshift.cxvwoeu3kuea.us-west-2.redshift.amazonaws.com, Port: 5439, Schema: dev, Login: awsuser, Password: XXXXXXXX, extra: None
[2021-04-26 12:34:52,168] {dbapi.py:180} INFO - Running statement: 
             COPY staging_events 
             FROM '/offor_data/log_data/2018/11/*'
             FORMAT AS JSON 'log_json_path.json'
                  , parameters: None
[2021-04-26 12:34:52,684] {taskinstance.py:1482} ERROR - Task failed with exception
Traceback (most recent call last):
  File "/home/airflow/.local/lib/python3.6/site-packages/airflow/models/taskinstance.py", line 1138, in _run_raw_task
    self._prepare_and_execute_task_with_callbacks(context, task)
  File "/home/airflow/.local/lib/python3.6/site-packages/airflow/models/taskinstance.py", line 1311, in _prepare_and_execute_task_with_callbacks
    result = self._execute_task(context, task_copy)
  File "/home/airflow/.local/lib/python3.6/site-packages/airflow/models/taskinstance.py", line 1341, in _execute_task
    result = task_copy.execute(context=context)
  File "/opt/airflow/plugins/operators/stage_redshift.py", line 80, in execute
    redshift.run(execution_sql)
  File "/home/airflow/.local/lib/python3.6/site-packages/airflow/hooks/dbapi.py", line 184, in run
    cur.execute(sql_statement)
psycopg2.errors.InternalError_: LOAD source is not supported. (Hint: only S3 or DynamoDB or EMR based load is allowed)

[2021-04-26 12:34:52,709] {taskinstance.py:1532} INFO - Marking task as UP_FOR_RETRY. dag_id=project_dag, task_id=Stage_events, execution_date=20200501T000000, start_date=20210426T123446, end_date=20210426T123452
[2021-04-26 12:34:52,983] {local_task_job.py:146} INFO - Task exited with return code 1
[2021-04-27 20:16:47,706] {taskinstance.py:877} INFO - Dependencies all met for <TaskInstance: project_dag.Stage_events 2020-05-01T00:00:00+00:00 [queued]>
[2021-04-27 20:16:47,828] {taskinstance.py:877} INFO - Dependencies all met for <TaskInstance: project_dag.Stage_events 2020-05-01T00:00:00+00:00 [queued]>
[2021-04-27 20:16:47,829] {taskinstance.py:1068} INFO - 
--------------------------------------------------------------------------------
[2021-04-27 20:16:47,832] {taskinstance.py:1069} INFO - Starting attempt 1 of 2
[2021-04-27 20:16:47,833] {taskinstance.py:1070} INFO - 
--------------------------------------------------------------------------------
[2021-04-27 20:16:47,873] {taskinstance.py:1089} INFO - Executing <Task(StageToRedshiftOperator): Stage_events> on 2020-05-01T00:00:00+00:00
[2021-04-27 20:16:47,982] {standard_task_runner.py:76} INFO - Running: ['airflow', 'tasks', 'run', 'project_dag', 'Stage_events', '2020-05-01T00:00:00+00:00', '--job-id', '50', '--pool', 'default_pool', '--raw', '--subdir', 'DAGS_FOLDER/udac_example_dag.py', '--cfg-path', '/tmp/tmp09muwcs1', '--error-file', '/tmp/tmp7jwgvr63']
[2021-04-27 20:16:47,983] {standard_task_runner.py:77} INFO - Job 50: Subtask Stage_events
[2021-04-27 20:16:47,979] {standard_task_runner.py:52} INFO - Started process 136 to run task
[2021-04-27 20:16:48,113] {logging_mixin.py:104} INFO - Running <TaskInstance: project_dag.Stage_events 2020-05-01T00:00:00+00:00 [running]> on host 88b3af0c26c0
[2021-04-27 20:16:48,291] {taskinstance.py:1283} INFO - Exporting the following env vars:
AIRFLOW_CTX_DAG_EMAIL=ernestoffor@gmail.com.com
AIRFLOW_CTX_DAG_OWNER=udacity
AIRFLOW_CTX_DAG_ID=project_dag
AIRFLOW_CTX_TASK_ID=Stage_events
AIRFLOW_CTX_EXECUTION_DATE=2020-05-01T00:00:00+00:00
AIRFLOW_CTX_DAG_RUN_ID=scheduled__2020-05-01T00:00:00+00:00
[2021-04-27 20:16:48,295] {stage_redshift.py:65} INFO - Start implementation of StageToRedshiftOperator
[2021-04-27 20:16:48,298] {taskinstance.py:1482} ERROR - Task failed with exception
Traceback (most recent call last):
  File "/home/airflow/.local/lib/python3.6/site-packages/airflow/models/taskinstance.py", line 1138, in _run_raw_task
    self._prepare_and_execute_task_with_callbacks(context, task)
  File "/home/airflow/.local/lib/python3.6/site-packages/airflow/models/taskinstance.py", line 1311, in _prepare_and_execute_task_with_callbacks
    result = self._execute_task(context, task_copy)
  File "/home/airflow/.local/lib/python3.6/site-packages/airflow/models/taskinstance.py", line 1341, in _execute_task
    result = task_copy.execute(context=context)
  File "/opt/airflow/plugins/operators/stage_redshift.py", line 66, in execute
    s3 = S3Hook(aws_conn_id=self.aws_credentials_id)
AttributeError: 'StageToRedshiftOperator' object has no attribute 'aws_credentials_id'
[2021-04-27 20:16:48,316] {taskinstance.py:1532} INFO - Marking task as UP_FOR_RETRY. dag_id=project_dag, task_id=Stage_events, execution_date=20200501T000000, start_date=20210427T201647, end_date=20210427T201648
[2021-04-27 20:16:48,482] {local_task_job.py:146} INFO - Task exited with return code 1
[2021-04-27 20:34:11,656] {taskinstance.py:877} INFO - Dependencies all met for <TaskInstance: project_dag.Stage_events 2020-05-01T00:00:00+00:00 [queued]>
[2021-04-27 20:34:11,748] {taskinstance.py:877} INFO - Dependencies all met for <TaskInstance: project_dag.Stage_events 2020-05-01T00:00:00+00:00 [queued]>
[2021-04-27 20:34:11,752] {taskinstance.py:1068} INFO - 
--------------------------------------------------------------------------------
[2021-04-27 20:34:11,755] {taskinstance.py:1069} INFO - Starting attempt 1 of 2
[2021-04-27 20:34:11,756] {taskinstance.py:1070} INFO - 
--------------------------------------------------------------------------------
[2021-04-27 20:34:11,848] {taskinstance.py:1089} INFO - Executing <Task(StageToRedshiftOperator): Stage_events> on 2020-05-01T00:00:00+00:00
[2021-04-27 20:34:11,893] {standard_task_runner.py:76} INFO - Running: ['airflow', 'tasks', 'run', 'project_dag', 'Stage_events', '2020-05-01T00:00:00+00:00', '--job-id', '47', '--pool', 'default_pool', '--raw', '--subdir', 'DAGS_FOLDER/udac_example_dag.py', '--cfg-path', '/tmp/tmpz1wykuq_', '--error-file', '/tmp/tmpwz8eyen0']
[2021-04-27 20:34:11,870] {standard_task_runner.py:52} INFO - Started process 128 to run task
[2021-04-27 20:34:11,908] {standard_task_runner.py:77} INFO - Job 47: Subtask Stage_events
[2021-04-27 20:34:12,447] {logging_mixin.py:104} INFO - Running <TaskInstance: project_dag.Stage_events 2020-05-01T00:00:00+00:00 [running]> on host 478c7ec349b0
[2021-04-27 20:34:13,427] {taskinstance.py:1283} INFO - Exporting the following env vars:
AIRFLOW_CTX_DAG_EMAIL=ernestoffor@gmail.com.com
AIRFLOW_CTX_DAG_OWNER=udacity
AIRFLOW_CTX_DAG_ID=project_dag
AIRFLOW_CTX_TASK_ID=Stage_events
AIRFLOW_CTX_EXECUTION_DATE=2020-05-01T00:00:00+00:00
AIRFLOW_CTX_DAG_RUN_ID=scheduled__2020-05-01T00:00:00+00:00
[2021-04-27 20:34:13,428] {stage_redshift.py:67} INFO - Start implementation of StageToRedshiftOperator
[2021-04-27 20:34:13,429] {stage_redshift.py:74} INFO - Preparing destination Redshift table
[2021-04-27 20:34:13,494] {base.py:78} INFO - Using connection to: id: redshift. Host: redshift.cxvwoeu3kuea.us-west-2.redshift.amazonaws.com, Port: 5439, Schema: dev, Login: awsuser, Password: XXXXXXXX, extra: None
[2021-04-27 20:34:14,918] {dbapi.py:180} INFO - Running statement: DELETE FROM staging_events, parameters: None
[2021-04-27 20:34:15,358] {dbapi.py:186} INFO - Rows affected: 0
[2021-04-27 20:34:15,647] {stage_redshift.py:77} INFO - Getting data from S3 to Redshift
[2021-04-27 20:34:17,348] {taskinstance.py:1482} ERROR - Task failed with exception
Traceback (most recent call last):
  File "/home/airflow/.local/lib/python3.6/site-packages/airflow/models/taskinstance.py", line 1138, in _run_raw_task
    self._prepare_and_execute_task_with_callbacks(context, task)
  File "/home/airflow/.local/lib/python3.6/site-packages/airflow/models/taskinstance.py", line 1311, in _prepare_and_execute_task_with_callbacks
    result = self._execute_task(context, task_copy)
  File "/home/airflow/.local/lib/python3.6/site-packages/airflow/models/taskinstance.py", line 1341, in _execute_task
    result = task_copy.execute(context=context)
  File "/opt/airflow/plugins/operators/stage_redshift.py", line 83, in execute
    s3.get_credentials().access_key,
  File "/home/airflow/.local/lib/python3.6/site-packages/airflow/providers/amazon/aws/hooks/base_aws.py", line 478, in get_credentials
    return session.get_credentials().get_frozen_credentials()
AttributeError: 'NoneType' object has no attribute 'get_frozen_credentials'
[2021-04-27 20:34:17,353] {taskinstance.py:1532} INFO - Marking task as UP_FOR_RETRY. dag_id=project_dag, task_id=Stage_events, execution_date=20200501T000000, start_date=20210427T203411, end_date=20210427T203417
[2021-04-27 20:34:17,484] {local_task_job.py:146} INFO - Task exited with return code 1
