[2021-04-24 11:40:02,920] {taskinstance.py:877} INFO - Dependencies all met for <TaskInstance: project_dag.Stage_events 2020-04-01T00:00:00+00:00 [queued]>
[2021-04-24 11:40:03,058] {taskinstance.py:877} INFO - Dependencies all met for <TaskInstance: project_dag.Stage_events 2020-04-01T00:00:00+00:00 [queued]>
[2021-04-24 11:40:03,059] {taskinstance.py:1068} INFO - 
--------------------------------------------------------------------------------
[2021-04-24 11:40:03,059] {taskinstance.py:1069} INFO - Starting attempt 1 of 2
[2021-04-24 11:40:03,059] {taskinstance.py:1070} INFO - 
--------------------------------------------------------------------------------
[2021-04-24 11:40:03,214] {taskinstance.py:1089} INFO - Executing <Task(StageToRedshiftOperator): Stage_events> on 2020-04-01T00:00:00+00:00
[2021-04-24 11:40:03,306] {standard_task_runner.py:76} INFO - Running: ['airflow', 'tasks', 'run', 'project_dag', 'Stage_events', '2020-04-01T00:00:00+00:00', '--job-id', '46', '--pool', 'default_pool', '--raw', '--subdir', 'DAGS_FOLDER/udac_example_dag.py', '--cfg-path', '/tmp/tmpcgg2rio4', '--error-file', '/tmp/tmphqvtt8ff']
[2021-04-24 11:40:03,307] {standard_task_runner.py:77} INFO - Job 46: Subtask Stage_events
[2021-04-24 11:40:03,252] {standard_task_runner.py:52} INFO - Started process 130 to run task
[2021-04-24 11:40:03,955] {logging_mixin.py:104} INFO - Running <TaskInstance: project_dag.Stage_events 2020-04-01T00:00:00+00:00 [running]> on host 88dcd2a12842
[2021-04-24 11:40:04,624] {taskinstance.py:1283} INFO - Exporting the following env vars:
AIRFLOW_CTX_DAG_EMAIL=ernest@gmail.com.com
AIRFLOW_CTX_DAG_OWNER=udacity
AIRFLOW_CTX_DAG_ID=project_dag
AIRFLOW_CTX_TASK_ID=Stage_events
AIRFLOW_CTX_EXECUTION_DATE=2020-04-01T00:00:00+00:00
AIRFLOW_CTX_DAG_RUN_ID=scheduled__2020-04-01T00:00:00+00:00
[2021-04-24 11:40:04,633] {stage_redshift.py:38} INFO - Start implementation of StageToRedshiftOperator
[2021-04-24 11:40:04,796] {taskinstance.py:1482} ERROR - Task failed with exception
Traceback (most recent call last):
  File "/home/airflow/.local/lib/python3.6/site-packages/airflow/models/taskinstance.py", line 1138, in _run_raw_task
    self._prepare_and_execute_task_with_callbacks(context, task)
  File "/home/airflow/.local/lib/python3.6/site-packages/airflow/models/taskinstance.py", line 1311, in _prepare_and_execute_task_with_callbacks
    result = self._execute_task(context, task_copy)
  File "/home/airflow/.local/lib/python3.6/site-packages/airflow/models/taskinstance.py", line 1341, in _execute_task
    result = task_copy.execute(context=context)
  File "/opt/airflow/plugins/operators/stage_redshift.py", line 39, in execute
    aws_hook = AwsHook(self.aws_credentials_id)
  File "/home/airflow/.local/lib/python3.6/site-packages/airflow/contrib/hooks/aws_hook.py", line 41, in __init__
    super().__init__(*args, **kwargs)
  File "/home/airflow/.local/lib/python3.6/site-packages/airflow/providers/amazon/aws/hooks/base_aws.py", line 360, in __init__
    raise AirflowException('Either client_type or resource_type must be provided.')
airflow.exceptions.AirflowException: Either client_type or resource_type must be provided.
[2021-04-24 11:40:04,814] {taskinstance.py:1532} INFO - Marking task as UP_FOR_RETRY. dag_id=project_dag, task_id=Stage_events, execution_date=20200401T000000, start_date=20210424T114002, end_date=20210424T114004
[2021-04-24 11:40:05,166] {local_task_job.py:146} INFO - Task exited with return code 1
[2021-04-27 20:15:54,788] {taskinstance.py:877} INFO - Dependencies all met for <TaskInstance: project_dag.Stage_events 2020-04-01T00:00:00+00:00 [queued]>
[2021-04-27 20:15:55,368] {taskinstance.py:877} INFO - Dependencies all met for <TaskInstance: project_dag.Stage_events 2020-04-01T00:00:00+00:00 [queued]>
[2021-04-27 20:15:55,369] {taskinstance.py:1068} INFO - 
--------------------------------------------------------------------------------
[2021-04-27 20:15:55,369] {taskinstance.py:1069} INFO - Starting attempt 1 of 2
[2021-04-27 20:15:55,369] {taskinstance.py:1070} INFO - 
--------------------------------------------------------------------------------
[2021-04-27 20:15:55,849] {taskinstance.py:1089} INFO - Executing <Task(StageToRedshiftOperator): Stage_events> on 2020-04-01T00:00:00+00:00
[2021-04-27 20:15:55,995] {standard_task_runner.py:52} INFO - Started process 96 to run task
[2021-04-27 20:15:56,597] {standard_task_runner.py:76} INFO - Running: ['airflow', 'tasks', 'run', 'project_dag', 'Stage_events', '2020-04-01T00:00:00+00:00', '--job-id', '34', '--pool', 'default_pool', '--raw', '--subdir', 'DAGS_FOLDER/udac_example_dag.py', '--cfg-path', '/tmp/tmph_g3v2iu', '--error-file', '/tmp/tmpxax982ot']
[2021-04-27 20:15:56,700] {standard_task_runner.py:77} INFO - Job 34: Subtask Stage_events
[2021-04-27 20:15:58,945] {logging_mixin.py:104} INFO - Running <TaskInstance: project_dag.Stage_events 2020-04-01T00:00:00+00:00 [running]> on host 88b3af0c26c0
[2021-04-27 20:16:01,065] {taskinstance.py:1283} INFO - Exporting the following env vars:
AIRFLOW_CTX_DAG_EMAIL=ernestoffor@gmail.com.com
AIRFLOW_CTX_DAG_OWNER=udacity
AIRFLOW_CTX_DAG_ID=project_dag
AIRFLOW_CTX_TASK_ID=Stage_events
AIRFLOW_CTX_EXECUTION_DATE=2020-04-01T00:00:00+00:00
AIRFLOW_CTX_DAG_RUN_ID=scheduled__2020-04-01T00:00:00+00:00
[2021-04-27 20:16:01,073] {stage_redshift.py:65} INFO - Start implementation of StageToRedshiftOperator
[2021-04-27 20:16:01,153] {taskinstance.py:1482} ERROR - Task failed with exception
Traceback (most recent call last):
  File "/home/airflow/.local/lib/python3.6/site-packages/airflow/models/taskinstance.py", line 1138, in _run_raw_task
    self._prepare_and_execute_task_with_callbacks(context, task)
  File "/home/airflow/.local/lib/python3.6/site-packages/airflow/models/taskinstance.py", line 1311, in _prepare_and_execute_task_with_callbacks
    result = self._execute_task(context, task_copy)
  File "/home/airflow/.local/lib/python3.6/site-packages/airflow/models/taskinstance.py", line 1341, in _execute_task
    result = task_copy.execute(context=context)
  File "/opt/airflow/plugins/operators/stage_redshift.py", line 66, in execute
    s3 = S3Hook(aws_conn_id=self.aws_credentials_id)
AttributeError: 'StageToRedshiftOperator' object has no attribute 'aws_credentials_id'
[2021-04-27 20:16:01,256] {taskinstance.py:1532} INFO - Marking task as UP_FOR_RETRY. dag_id=project_dag, task_id=Stage_events, execution_date=20200401T000000, start_date=20210427T201554, end_date=20210427T201601
[2021-04-27 20:16:03,443] {local_task_job.py:146} INFO - Task exited with return code 1
[2021-04-27 20:34:05,506] {taskinstance.py:877} INFO - Dependencies all met for <TaskInstance: project_dag.Stage_events 2020-04-01T00:00:00+00:00 [queued]>
[2021-04-27 20:34:05,950] {taskinstance.py:877} INFO - Dependencies all met for <TaskInstance: project_dag.Stage_events 2020-04-01T00:00:00+00:00 [queued]>
[2021-04-27 20:34:05,952] {taskinstance.py:1068} INFO - 
--------------------------------------------------------------------------------
[2021-04-27 20:34:05,954] {taskinstance.py:1069} INFO - Starting attempt 1 of 2
[2021-04-27 20:34:05,960] {taskinstance.py:1070} INFO - 
--------------------------------------------------------------------------------
[2021-04-27 20:34:06,706] {taskinstance.py:1089} INFO - Executing <Task(StageToRedshiftOperator): Stage_events> on 2020-04-01T00:00:00+00:00
[2021-04-27 20:34:07,712] {standard_task_runner.py:76} INFO - Running: ['airflow', 'tasks', 'run', 'project_dag', 'Stage_events', '2020-04-01T00:00:00+00:00', '--job-id', '45', '--pool', 'default_pool', '--raw', '--subdir', 'DAGS_FOLDER/udac_example_dag.py', '--cfg-path', '/tmp/tmp7j8uve6v', '--error-file', '/tmp/tmpr6uyww_4']
[2021-04-27 20:34:07,713] {standard_task_runner.py:77} INFO - Job 45: Subtask Stage_events
[2021-04-27 20:34:07,195] {standard_task_runner.py:52} INFO - Started process 126 to run task
[2021-04-27 20:34:08,650] {logging_mixin.py:104} INFO - Running <TaskInstance: project_dag.Stage_events 2020-04-01T00:00:00+00:00 [running]> on host 478c7ec349b0
[2021-04-27 20:34:09,542] {taskinstance.py:1283} INFO - Exporting the following env vars:
AIRFLOW_CTX_DAG_EMAIL=ernestoffor@gmail.com.com
AIRFLOW_CTX_DAG_OWNER=udacity
AIRFLOW_CTX_DAG_ID=project_dag
AIRFLOW_CTX_TASK_ID=Stage_events
AIRFLOW_CTX_EXECUTION_DATE=2020-04-01T00:00:00+00:00
AIRFLOW_CTX_DAG_RUN_ID=scheduled__2020-04-01T00:00:00+00:00
[2021-04-27 20:34:09,543] {stage_redshift.py:67} INFO - Start implementation of StageToRedshiftOperator
[2021-04-27 20:34:09,638] {stage_redshift.py:74} INFO - Preparing destination Redshift table
[2021-04-27 20:34:09,907] {base.py:78} INFO - Using connection to: id: redshift. Host: redshift.cxvwoeu3kuea.us-west-2.redshift.amazonaws.com, Port: 5439, Schema: dev, Login: awsuser, Password: XXXXXXXX, extra: None
[2021-04-27 20:34:11,412] {dbapi.py:180} INFO - Running statement: DELETE FROM staging_events, parameters: None
[2021-04-27 20:34:11,857] {dbapi.py:186} INFO - Rows affected: 0
[2021-04-27 20:34:12,148] {stage_redshift.py:77} INFO - Getting data from S3 to Redshift
[2021-04-27 20:34:14,276] {taskinstance.py:1482} ERROR - Task failed with exception
Traceback (most recent call last):
  File "/home/airflow/.local/lib/python3.6/site-packages/airflow/models/taskinstance.py", line 1138, in _run_raw_task
    self._prepare_and_execute_task_with_callbacks(context, task)
  File "/home/airflow/.local/lib/python3.6/site-packages/airflow/models/taskinstance.py", line 1311, in _prepare_and_execute_task_with_callbacks
    result = self._execute_task(context, task_copy)
  File "/home/airflow/.local/lib/python3.6/site-packages/airflow/models/taskinstance.py", line 1341, in _execute_task
    result = task_copy.execute(context=context)
  File "/opt/airflow/plugins/operators/stage_redshift.py", line 83, in execute
    s3.get_credentials().access_key,
  File "/home/airflow/.local/lib/python3.6/site-packages/airflow/providers/amazon/aws/hooks/base_aws.py", line 478, in get_credentials
    return session.get_credentials().get_frozen_credentials()
AttributeError: 'NoneType' object has no attribute 'get_frozen_credentials'
[2021-04-27 20:34:14,282] {taskinstance.py:1532} INFO - Marking task as UP_FOR_RETRY. dag_id=project_dag, task_id=Stage_events, execution_date=20200401T000000, start_date=20210427T203405, end_date=20210427T203414
[2021-04-27 20:34:14,360] {local_task_job.py:146} INFO - Task exited with return code 1
