[2021-04-24 11:45:27,090] {taskinstance.py:877} INFO - Dependencies all met for <TaskInstance: project_dag.Stage_events 2020-04-01T00:00:00+00:00 [queued]>
[2021-04-24 11:45:27,519] {taskinstance.py:877} INFO - Dependencies all met for <TaskInstance: project_dag.Stage_events 2020-04-01T00:00:00+00:00 [queued]>
[2021-04-24 11:45:27,525] {taskinstance.py:1068} INFO - 
--------------------------------------------------------------------------------
[2021-04-24 11:45:27,569] {taskinstance.py:1069} INFO - Starting attempt 2 of 2
[2021-04-24 11:45:27,582] {taskinstance.py:1070} INFO - 
--------------------------------------------------------------------------------
[2021-04-24 11:45:28,039] {taskinstance.py:1089} INFO - Executing <Task(StageToRedshiftOperator): Stage_events> on 2020-04-01T00:00:00+00:00
[2021-04-24 11:45:28,498] {standard_task_runner.py:52} INFO - Started process 217 to run task
[2021-04-24 11:45:28,720] {standard_task_runner.py:76} INFO - Running: ['airflow', 'tasks', 'run', 'project_dag', 'Stage_events', '2020-04-01T00:00:00+00:00', '--job-id', '84', '--pool', 'default_pool', '--raw', '--subdir', 'DAGS_FOLDER/udac_example_dag.py', '--cfg-path', '/tmp/tmp88i1kytr', '--error-file', '/tmp/tmp81dns5yl']
[2021-04-24 11:45:28,734] {standard_task_runner.py:77} INFO - Job 84: Subtask Stage_events
[2021-04-24 11:45:30,887] {logging_mixin.py:104} INFO - Running <TaskInstance: project_dag.Stage_events 2020-04-01T00:00:00+00:00 [running]> on host 88dcd2a12842
[2021-04-24 11:45:32,677] {taskinstance.py:1283} INFO - Exporting the following env vars:
AIRFLOW_CTX_DAG_EMAIL=ernest@gmail.com.com
AIRFLOW_CTX_DAG_OWNER=udacity
AIRFLOW_CTX_DAG_ID=project_dag
AIRFLOW_CTX_TASK_ID=Stage_events
AIRFLOW_CTX_EXECUTION_DATE=2020-04-01T00:00:00+00:00
AIRFLOW_CTX_DAG_RUN_ID=scheduled__2020-04-01T00:00:00+00:00
[2021-04-24 11:45:32,679] {stage_redshift.py:38} INFO - Start implementation of StageToRedshiftOperator
[2021-04-24 11:45:32,722] {taskinstance.py:1482} ERROR - Task failed with exception
Traceback (most recent call last):
  File "/home/airflow/.local/lib/python3.6/site-packages/airflow/models/taskinstance.py", line 1138, in _run_raw_task
    self._prepare_and_execute_task_with_callbacks(context, task)
  File "/home/airflow/.local/lib/python3.6/site-packages/airflow/models/taskinstance.py", line 1311, in _prepare_and_execute_task_with_callbacks
    result = self._execute_task(context, task_copy)
  File "/home/airflow/.local/lib/python3.6/site-packages/airflow/models/taskinstance.py", line 1341, in _execute_task
    result = task_copy.execute(context=context)
  File "/opt/airflow/plugins/operators/stage_redshift.py", line 39, in execute
    aws_hook = AwsHook(self.aws_credentials_id)
  File "/home/airflow/.local/lib/python3.6/site-packages/airflow/contrib/hooks/aws_hook.py", line 41, in __init__
    super().__init__(*args, **kwargs)
  File "/home/airflow/.local/lib/python3.6/site-packages/airflow/providers/amazon/aws/hooks/base_aws.py", line 360, in __init__
    raise AirflowException('Either client_type or resource_type must be provided.')
airflow.exceptions.AirflowException: Either client_type or resource_type must be provided.
[2021-04-24 11:45:32,726] {taskinstance.py:1532} INFO - Marking task as FAILED. dag_id=project_dag, task_id=Stage_events, execution_date=20200401T000000, start_date=20210424T114527, end_date=20210424T114532
[2021-04-24 11:45:33,583] {configuration.py:352} WARNING - section/key [smtp/smtp_user] not found in config
[2021-04-24 11:45:33,759] {email.py:184} INFO - Email alerting: attempt 1
[2021-04-24 11:45:33,964] {configuration.py:352} WARNING - section/key [smtp/smtp_user] not found in config
[2021-04-24 11:45:33,984] {email.py:184} INFO - Email alerting: attempt 1
[2021-04-24 11:45:34,000] {taskinstance.py:1538} ERROR - Failed to send email to: ['ernest@gmail.com.com']
[2021-04-24 11:45:34,049] {taskinstance.py:1539} ERROR - [Errno 99] Cannot assign requested address
Traceback (most recent call last):
  File "/home/airflow/.local/lib/python3.6/site-packages/airflow/models/taskinstance.py", line 1138, in _run_raw_task
    self._prepare_and_execute_task_with_callbacks(context, task)
  File "/home/airflow/.local/lib/python3.6/site-packages/airflow/models/taskinstance.py", line 1311, in _prepare_and_execute_task_with_callbacks
    result = self._execute_task(context, task_copy)
  File "/home/airflow/.local/lib/python3.6/site-packages/airflow/models/taskinstance.py", line 1341, in _execute_task
    result = task_copy.execute(context=context)
  File "/opt/airflow/plugins/operators/stage_redshift.py", line 39, in execute
    aws_hook = AwsHook(self.aws_credentials_id)
  File "/home/airflow/.local/lib/python3.6/site-packages/airflow/contrib/hooks/aws_hook.py", line 41, in __init__
    super().__init__(*args, **kwargs)
  File "/home/airflow/.local/lib/python3.6/site-packages/airflow/providers/amazon/aws/hooks/base_aws.py", line 360, in __init__
    raise AirflowException('Either client_type or resource_type must be provided.')
airflow.exceptions.AirflowException: Either client_type or resource_type must be provided.

During handling of the above exception, another exception occurred:

Traceback (most recent call last):
  File "/home/airflow/.local/lib/python3.6/site-packages/airflow/models/taskinstance.py", line 1881, in email_alert
    send_email(self.task.email, subject, html_content)
  File "/home/airflow/.local/lib/python3.6/site-packages/airflow/utils/email.py", line 62, in send_email
    **kwargs,
  File "/home/airflow/.local/lib/python3.6/site-packages/airflow/utils/email.py", line 97, in send_email_smtp
    send_mime_email(e_from=smtp_mail_from, e_to=recipients, mime_msg=msg, dryrun=dryrun)
  File "/home/airflow/.local/lib/python3.6/site-packages/airflow/utils/email.py", line 186, in send_mime_email
    conn = _get_smtp_connection(smtp_host, smtp_port, smtp_timeout, smtp_ssl)
  File "/home/airflow/.local/lib/python3.6/site-packages/airflow/utils/email.py", line 220, in _get_smtp_connection
    else smtplib.SMTP(host=host, port=port, timeout=timeout)
  File "/usr/local/lib/python3.6/smtplib.py", line 251, in __init__
    (code, msg) = self.connect(host, port)
  File "/usr/local/lib/python3.6/smtplib.py", line 336, in connect
    self.sock = self._get_socket(host, port, self.timeout)
  File "/usr/local/lib/python3.6/smtplib.py", line 307, in _get_socket
    self.source_address)
  File "/usr/local/lib/python3.6/socket.py", line 724, in create_connection
    raise err
  File "/usr/local/lib/python3.6/socket.py", line 713, in create_connection
    sock.connect(sa)
OSError: [Errno 99] Cannot assign requested address

During handling of the above exception, another exception occurred:

Traceback (most recent call last):
  File "/home/airflow/.local/lib/python3.6/site-packages/airflow/models/taskinstance.py", line 1536, in handle_failure
    self.email_alert(error)
  File "/home/airflow/.local/lib/python3.6/site-packages/airflow/models/taskinstance.py", line 1883, in email_alert
    send_email(self.task.email, subject, html_content_err)
  File "/home/airflow/.local/lib/python3.6/site-packages/airflow/utils/email.py", line 62, in send_email
    **kwargs,
  File "/home/airflow/.local/lib/python3.6/site-packages/airflow/utils/email.py", line 97, in send_email_smtp
    send_mime_email(e_from=smtp_mail_from, e_to=recipients, mime_msg=msg, dryrun=dryrun)
  File "/home/airflow/.local/lib/python3.6/site-packages/airflow/utils/email.py", line 186, in send_mime_email
    conn = _get_smtp_connection(smtp_host, smtp_port, smtp_timeout, smtp_ssl)
  File "/home/airflow/.local/lib/python3.6/site-packages/airflow/utils/email.py", line 220, in _get_smtp_connection
    else smtplib.SMTP(host=host, port=port, timeout=timeout)
  File "/usr/local/lib/python3.6/smtplib.py", line 251, in __init__
    (code, msg) = self.connect(host, port)
  File "/usr/local/lib/python3.6/smtplib.py", line 336, in connect
    self.sock = self._get_socket(host, port, self.timeout)
  File "/usr/local/lib/python3.6/smtplib.py", line 307, in _get_socket
    self.source_address)
  File "/usr/local/lib/python3.6/socket.py", line 724, in create_connection
    raise err
  File "/usr/local/lib/python3.6/socket.py", line 713, in create_connection
    sock.connect(sa)
OSError: [Errno 99] Cannot assign requested address
[2021-04-24 11:45:34,811] {local_task_job.py:146} INFO - Task exited with return code 1
[2021-04-27 20:39:50,651] {taskinstance.py:877} INFO - Dependencies all met for <TaskInstance: project_dag.Stage_events 2020-04-01T00:00:00+00:00 [queued]>
[2021-04-27 20:39:51,056] {taskinstance.py:877} INFO - Dependencies all met for <TaskInstance: project_dag.Stage_events 2020-04-01T00:00:00+00:00 [queued]>
[2021-04-27 20:39:51,069] {taskinstance.py:1068} INFO - 
--------------------------------------------------------------------------------
[2021-04-27 20:39:51,092] {taskinstance.py:1069} INFO - Starting attempt 2 of 2
[2021-04-27 20:39:51,108] {taskinstance.py:1070} INFO - 
--------------------------------------------------------------------------------
[2021-04-27 20:39:51,573] {taskinstance.py:1089} INFO - Executing <Task(StageToRedshiftOperator): Stage_events> on 2020-04-01T00:00:00+00:00
[2021-04-27 20:39:51,856] {standard_task_runner.py:52} INFO - Started process 220 to run task
[2021-04-27 20:39:51,997] {standard_task_runner.py:76} INFO - Running: ['airflow', 'tasks', 'run', 'project_dag', 'Stage_events', '2020-04-01T00:00:00+00:00', '--job-id', '89', '--pool', 'default_pool', '--raw', '--subdir', 'DAGS_FOLDER/udac_example_dag.py', '--cfg-path', '/tmp/tmphttne3h8', '--error-file', '/tmp/tmpwzdflg96']
[2021-04-27 20:39:52,045] {standard_task_runner.py:77} INFO - Job 89: Subtask Stage_events
[2021-04-27 20:39:53,568] {logging_mixin.py:104} INFO - Running <TaskInstance: project_dag.Stage_events 2020-04-01T00:00:00+00:00 [running]> on host 478c7ec349b0
[2021-04-27 20:39:54,664] {taskinstance.py:1283} INFO - Exporting the following env vars:
AIRFLOW_CTX_DAG_EMAIL=ernestoffor@gmail.com.com
AIRFLOW_CTX_DAG_OWNER=udacity
AIRFLOW_CTX_DAG_ID=project_dag
AIRFLOW_CTX_TASK_ID=Stage_events
AIRFLOW_CTX_EXECUTION_DATE=2020-04-01T00:00:00+00:00
AIRFLOW_CTX_DAG_RUN_ID=scheduled__2020-04-01T00:00:00+00:00
[2021-04-27 20:39:54,673] {stage_redshift.py:67} INFO - Start implementation of StageToRedshiftOperator
[2021-04-27 20:39:54,673] {stage_redshift.py:74} INFO - Preparing destination Redshift table
[2021-04-27 20:39:55,087] {base.py:78} INFO - Using connection to: id: redshift. Host: redshift.cxvwoeu3kuea.us-west-2.redshift.amazonaws.com, Port: 5439, Schema: dev, Login: awsuser, Password: XXXXXXXX, extra: None
[2021-04-27 20:39:56,762] {dbapi.py:180} INFO - Running statement: DELETE FROM staging_events, parameters: None
[2021-04-27 20:39:57,200] {dbapi.py:186} INFO - Rows affected: 0
[2021-04-27 20:39:57,489] {stage_redshift.py:77} INFO - Getting data from S3 to Redshift
[2021-04-27 20:40:01,112] {taskinstance.py:1482} ERROR - Task failed with exception
Traceback (most recent call last):
  File "/home/airflow/.local/lib/python3.6/site-packages/airflow/models/taskinstance.py", line 1138, in _run_raw_task
    self._prepare_and_execute_task_with_callbacks(context, task)
  File "/home/airflow/.local/lib/python3.6/site-packages/airflow/models/taskinstance.py", line 1311, in _prepare_and_execute_task_with_callbacks
    result = self._execute_task(context, task_copy)
  File "/home/airflow/.local/lib/python3.6/site-packages/airflow/models/taskinstance.py", line 1341, in _execute_task
    result = task_copy.execute(context=context)
  File "/opt/airflow/plugins/operators/stage_redshift.py", line 83, in execute
    s3.get_credentials().access_key,
  File "/home/airflow/.local/lib/python3.6/site-packages/airflow/providers/amazon/aws/hooks/base_aws.py", line 478, in get_credentials
    return session.get_credentials().get_frozen_credentials()
AttributeError: 'NoneType' object has no attribute 'get_frozen_credentials'
[2021-04-27 20:40:01,128] {taskinstance.py:1532} INFO - Marking task as FAILED. dag_id=project_dag, task_id=Stage_events, execution_date=20200401T000000, start_date=20210427T203950, end_date=20210427T204001
[2021-04-27 20:40:01,552] {local_task_job.py:146} INFO - Task exited with return code 1
