[2021-04-24 11:45:25,443] {taskinstance.py:877} INFO - Dependencies all met for <TaskInstance: project_dag.Stage_events 2020-02-01T00:00:00+00:00 [queued]>
[2021-04-24 11:45:26,034] {taskinstance.py:877} INFO - Dependencies all met for <TaskInstance: project_dag.Stage_events 2020-02-01T00:00:00+00:00 [queued]>
[2021-04-24 11:45:26,034] {taskinstance.py:1068} INFO - 
--------------------------------------------------------------------------------
[2021-04-24 11:45:26,035] {taskinstance.py:1069} INFO - Starting attempt 2 of 2
[2021-04-24 11:45:26,035] {taskinstance.py:1070} INFO - 
--------------------------------------------------------------------------------
[2021-04-24 11:45:26,651] {taskinstance.py:1089} INFO - Executing <Task(StageToRedshiftOperator): Stage_events> on 2020-02-01T00:00:00+00:00
[2021-04-24 11:45:26,830] {standard_task_runner.py:76} INFO - Running: ['airflow', 'tasks', 'run', 'project_dag', 'Stage_events', '2020-02-01T00:00:00+00:00', '--job-id', '81', '--pool', 'default_pool', '--raw', '--subdir', 'DAGS_FOLDER/udac_example_dag.py', '--cfg-path', '/tmp/tmpdc0yx17m', '--error-file', '/tmp/tmpe_kgnrb7']
[2021-04-24 11:45:26,830] {standard_task_runner.py:77} INFO - Job 81: Subtask Stage_events
[2021-04-24 11:45:26,776] {standard_task_runner.py:52} INFO - Started process 211 to run task
[2021-04-24 11:45:27,810] {logging_mixin.py:104} INFO - Running <TaskInstance: project_dag.Stage_events 2020-02-01T00:00:00+00:00 [running]> on host 88dcd2a12842
[2021-04-24 11:45:29,863] {taskinstance.py:1283} INFO - Exporting the following env vars:
AIRFLOW_CTX_DAG_EMAIL=ernest@gmail.com.com
AIRFLOW_CTX_DAG_OWNER=udacity
AIRFLOW_CTX_DAG_ID=project_dag
AIRFLOW_CTX_TASK_ID=Stage_events
AIRFLOW_CTX_EXECUTION_DATE=2020-02-01T00:00:00+00:00
AIRFLOW_CTX_DAG_RUN_ID=scheduled__2020-02-01T00:00:00+00:00
[2021-04-24 11:45:29,864] {stage_redshift.py:38} INFO - Start implementation of StageToRedshiftOperator
[2021-04-24 11:45:30,091] {taskinstance.py:1482} ERROR - Task failed with exception
Traceback (most recent call last):
  File "/home/airflow/.local/lib/python3.6/site-packages/airflow/models/taskinstance.py", line 1138, in _run_raw_task
    self._prepare_and_execute_task_with_callbacks(context, task)
  File "/home/airflow/.local/lib/python3.6/site-packages/airflow/models/taskinstance.py", line 1311, in _prepare_and_execute_task_with_callbacks
    result = self._execute_task(context, task_copy)
  File "/home/airflow/.local/lib/python3.6/site-packages/airflow/models/taskinstance.py", line 1341, in _execute_task
    result = task_copy.execute(context=context)
  File "/opt/airflow/plugins/operators/stage_redshift.py", line 39, in execute
    aws_hook = AwsHook(self.aws_credentials_id)
  File "/home/airflow/.local/lib/python3.6/site-packages/airflow/contrib/hooks/aws_hook.py", line 41, in __init__
    super().__init__(*args, **kwargs)
  File "/home/airflow/.local/lib/python3.6/site-packages/airflow/providers/amazon/aws/hooks/base_aws.py", line 360, in __init__
    raise AirflowException('Either client_type or resource_type must be provided.')
airflow.exceptions.AirflowException: Either client_type or resource_type must be provided.
[2021-04-24 11:45:30,227] {taskinstance.py:1532} INFO - Marking task as FAILED. dag_id=project_dag, task_id=Stage_events, execution_date=20200201T000000, start_date=20210424T114525, end_date=20210424T114530
[2021-04-24 11:45:30,895] {configuration.py:352} WARNING - section/key [smtp/smtp_user] not found in config
[2021-04-24 11:45:30,895] {email.py:184} INFO - Email alerting: attempt 1
[2021-04-24 11:45:30,939] {configuration.py:352} WARNING - section/key [smtp/smtp_user] not found in config
[2021-04-24 11:45:30,939] {email.py:184} INFO - Email alerting: attempt 1
[2021-04-24 11:45:30,974] {taskinstance.py:1538} ERROR - Failed to send email to: ['ernest@gmail.com.com']
[2021-04-24 11:45:30,991] {taskinstance.py:1539} ERROR - [Errno 99] Cannot assign requested address
Traceback (most recent call last):
  File "/home/airflow/.local/lib/python3.6/site-packages/airflow/models/taskinstance.py", line 1138, in _run_raw_task
    self._prepare_and_execute_task_with_callbacks(context, task)
  File "/home/airflow/.local/lib/python3.6/site-packages/airflow/models/taskinstance.py", line 1311, in _prepare_and_execute_task_with_callbacks
    result = self._execute_task(context, task_copy)
  File "/home/airflow/.local/lib/python3.6/site-packages/airflow/models/taskinstance.py", line 1341, in _execute_task
    result = task_copy.execute(context=context)
  File "/opt/airflow/plugins/operators/stage_redshift.py", line 39, in execute
    aws_hook = AwsHook(self.aws_credentials_id)
  File "/home/airflow/.local/lib/python3.6/site-packages/airflow/contrib/hooks/aws_hook.py", line 41, in __init__
    super().__init__(*args, **kwargs)
  File "/home/airflow/.local/lib/python3.6/site-packages/airflow/providers/amazon/aws/hooks/base_aws.py", line 360, in __init__
    raise AirflowException('Either client_type or resource_type must be provided.')
airflow.exceptions.AirflowException: Either client_type or resource_type must be provided.

During handling of the above exception, another exception occurred:

Traceback (most recent call last):
  File "/home/airflow/.local/lib/python3.6/site-packages/airflow/models/taskinstance.py", line 1881, in email_alert
    send_email(self.task.email, subject, html_content)
  File "/home/airflow/.local/lib/python3.6/site-packages/airflow/utils/email.py", line 62, in send_email
    **kwargs,
  File "/home/airflow/.local/lib/python3.6/site-packages/airflow/utils/email.py", line 97, in send_email_smtp
    send_mime_email(e_from=smtp_mail_from, e_to=recipients, mime_msg=msg, dryrun=dryrun)
  File "/home/airflow/.local/lib/python3.6/site-packages/airflow/utils/email.py", line 186, in send_mime_email
    conn = _get_smtp_connection(smtp_host, smtp_port, smtp_timeout, smtp_ssl)
  File "/home/airflow/.local/lib/python3.6/site-packages/airflow/utils/email.py", line 220, in _get_smtp_connection
    else smtplib.SMTP(host=host, port=port, timeout=timeout)
  File "/usr/local/lib/python3.6/smtplib.py", line 251, in __init__
    (code, msg) = self.connect(host, port)
  File "/usr/local/lib/python3.6/smtplib.py", line 336, in connect
    self.sock = self._get_socket(host, port, self.timeout)
  File "/usr/local/lib/python3.6/smtplib.py", line 307, in _get_socket
    self.source_address)
  File "/usr/local/lib/python3.6/socket.py", line 724, in create_connection
    raise err
  File "/usr/local/lib/python3.6/socket.py", line 713, in create_connection
    sock.connect(sa)
OSError: [Errno 99] Cannot assign requested address

During handling of the above exception, another exception occurred:

Traceback (most recent call last):
  File "/home/airflow/.local/lib/python3.6/site-packages/airflow/models/taskinstance.py", line 1536, in handle_failure
    self.email_alert(error)
  File "/home/airflow/.local/lib/python3.6/site-packages/airflow/models/taskinstance.py", line 1883, in email_alert
    send_email(self.task.email, subject, html_content_err)
  File "/home/airflow/.local/lib/python3.6/site-packages/airflow/utils/email.py", line 62, in send_email
    **kwargs,
  File "/home/airflow/.local/lib/python3.6/site-packages/airflow/utils/email.py", line 97, in send_email_smtp
    send_mime_email(e_from=smtp_mail_from, e_to=recipients, mime_msg=msg, dryrun=dryrun)
  File "/home/airflow/.local/lib/python3.6/site-packages/airflow/utils/email.py", line 186, in send_mime_email
    conn = _get_smtp_connection(smtp_host, smtp_port, smtp_timeout, smtp_ssl)
  File "/home/airflow/.local/lib/python3.6/site-packages/airflow/utils/email.py", line 220, in _get_smtp_connection
    else smtplib.SMTP(host=host, port=port, timeout=timeout)
  File "/usr/local/lib/python3.6/smtplib.py", line 251, in __init__
    (code, msg) = self.connect(host, port)
  File "/usr/local/lib/python3.6/smtplib.py", line 336, in connect
    self.sock = self._get_socket(host, port, self.timeout)
  File "/usr/local/lib/python3.6/smtplib.py", line 307, in _get_socket
    self.source_address)
  File "/usr/local/lib/python3.6/socket.py", line 724, in create_connection
    raise err
  File "/usr/local/lib/python3.6/socket.py", line 713, in create_connection
    sock.connect(sa)
OSError: [Errno 99] Cannot assign requested address
[2021-04-24 11:45:31,778] {local_task_job.py:146} INFO - Task exited with return code 1
[2021-04-26 09:12:43,687] {taskinstance.py:877} INFO - Dependencies all met for <TaskInstance: project_dag.Stage_events 2020-02-01T00:00:00+00:00 [queued]>
[2021-04-26 09:12:43,782] {taskinstance.py:877} INFO - Dependencies all met for <TaskInstance: project_dag.Stage_events 2020-02-01T00:00:00+00:00 [queued]>
[2021-04-26 09:12:43,783] {taskinstance.py:1068} INFO - 
--------------------------------------------------------------------------------
[2021-04-26 09:12:43,783] {taskinstance.py:1069} INFO - Starting attempt 2 of 2
[2021-04-26 09:12:43,783] {taskinstance.py:1070} INFO - 
--------------------------------------------------------------------------------
[2021-04-26 09:12:43,900] {taskinstance.py:1089} INFO - Executing <Task(StageToRedshiftOperator): Stage_events> on 2020-02-01T00:00:00+00:00
[2021-04-26 09:12:43,930] {standard_task_runner.py:52} INFO - Started process 130 to run task
[2021-04-26 09:12:43,986] {standard_task_runner.py:76} INFO - Running: ['airflow', 'tasks', 'run', 'project_dag', 'Stage_events', '2020-02-01T00:00:00+00:00', '--job-id', '45', '--pool', 'default_pool', '--raw', '--subdir', 'DAGS_FOLDER/udac_example_dag.py', '--cfg-path', '/tmp/tmpip03ihyk', '--error-file', '/tmp/tmpfkf3xgld']
[2021-04-26 09:12:44,008] {standard_task_runner.py:77} INFO - Job 45: Subtask Stage_events
[2021-04-26 09:12:44,568] {logging_mixin.py:104} INFO - Running <TaskInstance: project_dag.Stage_events 2020-02-01T00:00:00+00:00 [running]> on host b5c40a6f08c7
[2021-04-26 09:12:45,068] {taskinstance.py:1283} INFO - Exporting the following env vars:
AIRFLOW_CTX_DAG_EMAIL=ernestoffor@gmail.com.com
AIRFLOW_CTX_DAG_OWNER=udacity
AIRFLOW_CTX_DAG_ID=project_dag
AIRFLOW_CTX_TASK_ID=Stage_events
AIRFLOW_CTX_EXECUTION_DATE=2020-02-01T00:00:00+00:00
AIRFLOW_CTX_DAG_RUN_ID=scheduled__2020-02-01T00:00:00+00:00
[2021-04-26 09:12:45,069] {stage_redshift.py:63} INFO - Start implementation of StageToRedshiftOperator
[2021-04-26 09:12:45,069] {stage_redshift.py:68} INFO - Preparing destination Redshift table
[2021-04-26 09:12:45,229] {base.py:78} INFO - Using connection to: id: redshift. Host: redshift.cxvwoeu3kuea.us-west-2.redshift.amazonaws.com, Port: 5439, Schema: dev, Login: awsuser, Password: XXXXXXXX, extra: None
[2021-04-26 09:12:47,665] {dbapi.py:180} INFO - Running statement: DELETE FROM staging_events, parameters: None
[2021-04-26 09:12:48,097] {dbapi.py:186} INFO - Rows affected: 0
[2021-04-26 09:12:48,382] {stage_redshift.py:71} INFO - Getting data from S3 to Redshift
[2021-04-26 09:12:48,399] {base.py:78} INFO - Using connection to: id: redshift. Host: redshift.cxvwoeu3kuea.us-west-2.redshift.amazonaws.com, Port: 5439, Schema: dev, Login: awsuser, Password: XXXXXXXX, extra: None
[2021-04-26 09:12:49,799] {dbapi.py:180} INFO - Running statement: 
             COPY staging_events 
             FROM 's3://udacity-dend/log_data/2018/11/*'
             FORMAT AS JSON 'log_json_path.json'
             CREDENTIALS
             'aws_access_key_id=None;aws_secret_access_key=None'
                , parameters: None
[2021-04-26 09:12:50,329] {taskinstance.py:1482} ERROR - Task failed with exception
Traceback (most recent call last):
  File "/home/airflow/.local/lib/python3.6/site-packages/airflow/models/taskinstance.py", line 1138, in _run_raw_task
    self._prepare_and_execute_task_with_callbacks(context, task)
  File "/home/airflow/.local/lib/python3.6/site-packages/airflow/models/taskinstance.py", line 1311, in _prepare_and_execute_task_with_callbacks
    result = self._execute_task(context, task_copy)
  File "/home/airflow/.local/lib/python3.6/site-packages/airflow/models/taskinstance.py", line 1341, in _execute_task
    result = task_copy.execute(context=context)
  File "/opt/airflow/plugins/operators/stage_redshift.py", line 81, in execute
    redshift.run(execution_sql)
  File "/home/airflow/.local/lib/python3.6/site-packages/airflow/hooks/dbapi.py", line 184, in run
    cur.execute(sql_statement)
psycopg2.errors.InternalError_: S3ServiceException:The AWS Access Key Id you provided does not exist in our records.,Status 403,Error InvalidAccessKeyId,Rid 80QQR168PHNBWR3X,ExtRid py9J8AGGFQQU6t0ppXpo88UBkQMllNqngLsqv8CdvfY1JwFn/01khd/BoVgTULcoOF31jyqOKGw=,CanRetry 1
DETAIL:  
  -----------------------------------------------
  error:  S3ServiceException:The AWS Access Key Id you provided does not exist in our records.,Status 403,Error InvalidAccessKeyId,Rid 80QQR168PHNBWR3X,ExtRid py9J8AGGFQQU6t0ppXpo88UBkQMllNqngLsqv8CdvfY1JwFn/01khd/BoVgTULcoOF31jyqOKGw=,CanRetry 1
  code:      8001
  context:   Listing bucket=udacity-dend prefix=log_data/2018/11/*
  query:     308
  location:  s3_utility.cpp:654
  process:   padbmaster [pid=14139]
  -----------------------------------------------


[2021-04-26 09:12:50,335] {taskinstance.py:1532} INFO - Marking task as FAILED. dag_id=project_dag, task_id=Stage_events, execution_date=20200201T000000, start_date=20210426T091243, end_date=20210426T091250
[2021-04-26 09:12:50,564] {local_task_job.py:146} INFO - Task exited with return code 1
[2021-04-27 20:39:32,485] {taskinstance.py:877} INFO - Dependencies all met for <TaskInstance: project_dag.Stage_events 2020-02-01T00:00:00+00:00 [queued]>
[2021-04-27 20:39:33,515] {taskinstance.py:877} INFO - Dependencies all met for <TaskInstance: project_dag.Stage_events 2020-02-01T00:00:00+00:00 [queued]>
[2021-04-27 20:39:33,517] {taskinstance.py:1068} INFO - 
--------------------------------------------------------------------------------
[2021-04-27 20:39:33,519] {taskinstance.py:1069} INFO - Starting attempt 2 of 2
[2021-04-27 20:39:33,520] {taskinstance.py:1070} INFO - 
--------------------------------------------------------------------------------
[2021-04-27 20:39:34,040] {taskinstance.py:1089} INFO - Executing <Task(StageToRedshiftOperator): Stage_events> on 2020-02-01T00:00:00+00:00
[2021-04-27 20:39:34,428] {standard_task_runner.py:52} INFO - Started process 205 to run task
[2021-04-27 20:39:34,611] {standard_task_runner.py:76} INFO - Running: ['airflow', 'tasks', 'run', 'project_dag', 'Stage_events', '2020-02-01T00:00:00+00:00', '--job-id', '82', '--pool', 'default_pool', '--raw', '--subdir', 'DAGS_FOLDER/udac_example_dag.py', '--cfg-path', '/tmp/tmp9w44do8c', '--error-file', '/tmp/tmpvt3fbguz']
[2021-04-27 20:39:34,611] {standard_task_runner.py:77} INFO - Job 82: Subtask Stage_events
[2021-04-27 20:39:36,908] {logging_mixin.py:104} INFO - Running <TaskInstance: project_dag.Stage_events 2020-02-01T00:00:00+00:00 [running]> on host 478c7ec349b0
[2021-04-27 20:39:39,178] {taskinstance.py:1283} INFO - Exporting the following env vars:
AIRFLOW_CTX_DAG_EMAIL=ernestoffor@gmail.com.com
AIRFLOW_CTX_DAG_OWNER=udacity
AIRFLOW_CTX_DAG_ID=project_dag
AIRFLOW_CTX_TASK_ID=Stage_events
AIRFLOW_CTX_EXECUTION_DATE=2020-02-01T00:00:00+00:00
AIRFLOW_CTX_DAG_RUN_ID=scheduled__2020-02-01T00:00:00+00:00
[2021-04-27 20:39:39,178] {stage_redshift.py:67} INFO - Start implementation of StageToRedshiftOperator
[2021-04-27 20:39:39,179] {stage_redshift.py:74} INFO - Preparing destination Redshift table
[2021-04-27 20:39:39,389] {base.py:78} INFO - Using connection to: id: redshift. Host: redshift.cxvwoeu3kuea.us-west-2.redshift.amazonaws.com, Port: 5439, Schema: dev, Login: awsuser, Password: XXXXXXXX, extra: None
[2021-04-27 20:39:40,867] {dbapi.py:180} INFO - Running statement: DELETE FROM staging_events, parameters: None
[2021-04-27 20:39:41,327] {dbapi.py:186} INFO - Rows affected: 0
[2021-04-27 20:39:41,625] {stage_redshift.py:77} INFO - Getting data from S3 to Redshift
[2021-04-27 20:39:44,752] {taskinstance.py:1482} ERROR - Task failed with exception
Traceback (most recent call last):
  File "/home/airflow/.local/lib/python3.6/site-packages/airflow/models/taskinstance.py", line 1138, in _run_raw_task
    self._prepare_and_execute_task_with_callbacks(context, task)
  File "/home/airflow/.local/lib/python3.6/site-packages/airflow/models/taskinstance.py", line 1311, in _prepare_and_execute_task_with_callbacks
    result = self._execute_task(context, task_copy)
  File "/home/airflow/.local/lib/python3.6/site-packages/airflow/models/taskinstance.py", line 1341, in _execute_task
    result = task_copy.execute(context=context)
  File "/opt/airflow/plugins/operators/stage_redshift.py", line 83, in execute
    s3.get_credentials().access_key,
  File "/home/airflow/.local/lib/python3.6/site-packages/airflow/providers/amazon/aws/hooks/base_aws.py", line 478, in get_credentials
    return session.get_credentials().get_frozen_credentials()
AttributeError: 'NoneType' object has no attribute 'get_frozen_credentials'
[2021-04-27 20:39:44,763] {taskinstance.py:1532} INFO - Marking task as FAILED. dag_id=project_dag, task_id=Stage_events, execution_date=20200201T000000, start_date=20210427T203932, end_date=20210427T203944
[2021-04-27 20:39:45,918] {local_task_job.py:146} INFO - Task exited with return code 1
