[2021-04-24 11:46:12,816] {taskinstance.py:877} INFO - Dependencies all met for <TaskInstance: project_dag.Stage_events 2021-01-01T00:00:00+00:00 [queued]>
[2021-04-24 11:46:12,901] {taskinstance.py:877} INFO - Dependencies all met for <TaskInstance: project_dag.Stage_events 2021-01-01T00:00:00+00:00 [queued]>
[2021-04-24 11:46:12,902] {taskinstance.py:1068} INFO - 
--------------------------------------------------------------------------------
[2021-04-24 11:46:12,902] {taskinstance.py:1069} INFO - Starting attempt 1 of 2
[2021-04-24 11:46:12,902] {taskinstance.py:1070} INFO - 
--------------------------------------------------------------------------------
[2021-04-24 11:46:12,973] {taskinstance.py:1089} INFO - Executing <Task(StageToRedshiftOperator): Stage_events> on 2021-01-01T00:00:00+00:00
[2021-04-24 11:46:13,008] {standard_task_runner.py:76} INFO - Running: ['airflow', 'tasks', 'run', 'project_dag', 'Stage_events', '2021-01-01T00:00:00+00:00', '--job-id', '112', '--pool', 'default_pool', '--raw', '--subdir', 'DAGS_FOLDER/udac_example_dag.py', '--cfg-path', '/tmp/tmpt4enib8i', '--error-file', '/tmp/tmpfc0vmqdm']
[2021-04-24 11:46:13,020] {standard_task_runner.py:77} INFO - Job 112: Subtask Stage_events
[2021-04-24 11:46:12,988] {standard_task_runner.py:52} INFO - Started process 260 to run task
[2021-04-24 11:46:13,313] {logging_mixin.py:104} INFO - Running <TaskInstance: project_dag.Stage_events 2021-01-01T00:00:00+00:00 [running]> on host 88dcd2a12842
[2021-04-24 11:46:13,501] {taskinstance.py:1283} INFO - Exporting the following env vars:
AIRFLOW_CTX_DAG_EMAIL=ernest@gmail.com.com
AIRFLOW_CTX_DAG_OWNER=udacity
AIRFLOW_CTX_DAG_ID=project_dag
AIRFLOW_CTX_TASK_ID=Stage_events
AIRFLOW_CTX_EXECUTION_DATE=2021-01-01T00:00:00+00:00
AIRFLOW_CTX_DAG_RUN_ID=scheduled__2021-01-01T00:00:00+00:00
[2021-04-24 11:46:13,503] {stage_redshift.py:38} INFO - Start implementation of StageToRedshiftOperator
[2021-04-24 11:46:13,532] {taskinstance.py:1482} ERROR - Task failed with exception
Traceback (most recent call last):
  File "/home/airflow/.local/lib/python3.6/site-packages/airflow/models/taskinstance.py", line 1138, in _run_raw_task
    self._prepare_and_execute_task_with_callbacks(context, task)
  File "/home/airflow/.local/lib/python3.6/site-packages/airflow/models/taskinstance.py", line 1311, in _prepare_and_execute_task_with_callbacks
    result = self._execute_task(context, task_copy)
  File "/home/airflow/.local/lib/python3.6/site-packages/airflow/models/taskinstance.py", line 1341, in _execute_task
    result = task_copy.execute(context=context)
  File "/opt/airflow/plugins/operators/stage_redshift.py", line 39, in execute
    aws_hook = AwsHook(self.aws_credentials_id)
  File "/home/airflow/.local/lib/python3.6/site-packages/airflow/contrib/hooks/aws_hook.py", line 41, in __init__
    super().__init__(*args, **kwargs)
  File "/home/airflow/.local/lib/python3.6/site-packages/airflow/providers/amazon/aws/hooks/base_aws.py", line 360, in __init__
    raise AirflowException('Either client_type or resource_type must be provided.')
airflow.exceptions.AirflowException: Either client_type or resource_type must be provided.
[2021-04-24 11:46:13,555] {taskinstance.py:1532} INFO - Marking task as UP_FOR_RETRY. dag_id=project_dag, task_id=Stage_events, execution_date=20210101T000000, start_date=20210424T114612, end_date=20210424T114613
[2021-04-24 11:46:13,662] {local_task_job.py:146} INFO - Task exited with return code 1
[2021-04-26 09:08:32,369] {taskinstance.py:877} INFO - Dependencies all met for <TaskInstance: project_dag.Stage_events 2021-01-01T00:00:00+00:00 [queued]>
[2021-04-26 09:08:33,838] {taskinstance.py:877} INFO - Dependencies all met for <TaskInstance: project_dag.Stage_events 2021-01-01T00:00:00+00:00 [queued]>
[2021-04-26 09:08:33,838] {taskinstance.py:1068} INFO - 
--------------------------------------------------------------------------------
[2021-04-26 09:08:33,865] {taskinstance.py:1069} INFO - Starting attempt 1 of 2
[2021-04-26 09:08:33,865] {taskinstance.py:1070} INFO - 
--------------------------------------------------------------------------------
[2021-04-26 09:08:34,655] {taskinstance.py:1089} INFO - Executing <Task(StageToRedshiftOperator): Stage_events> on 2021-01-01T00:00:00+00:00
[2021-04-26 09:08:34,849] {standard_task_runner.py:52} INFO - Started process 113 to run task
[2021-04-26 09:08:35,184] {standard_task_runner.py:76} INFO - Running: ['airflow', 'tasks', 'run', 'project_dag', 'Stage_events', '2021-01-01T00:00:00+00:00', '--job-id', '32', '--pool', 'default_pool', '--raw', '--subdir', 'DAGS_FOLDER/udac_example_dag.py', '--cfg-path', '/tmp/tmpaj07nl9p', '--error-file', '/tmp/tmpzr5tfatr']
[2021-04-26 09:08:35,216] {standard_task_runner.py:77} INFO - Job 32: Subtask Stage_events
[2021-04-26 09:08:37,334] {logging_mixin.py:104} INFO - Running <TaskInstance: project_dag.Stage_events 2021-01-01T00:00:00+00:00 [running]> on host b5c40a6f08c7
[2021-04-26 09:08:38,671] {taskinstance.py:1283} INFO - Exporting the following env vars:
AIRFLOW_CTX_DAG_EMAIL=ernestoffor@gmail.com.com
AIRFLOW_CTX_DAG_OWNER=udacity
AIRFLOW_CTX_DAG_ID=project_dag
AIRFLOW_CTX_TASK_ID=Stage_events
AIRFLOW_CTX_EXECUTION_DATE=2021-01-01T00:00:00+00:00
AIRFLOW_CTX_DAG_RUN_ID=scheduled__2021-01-01T00:00:00+00:00
[2021-04-26 09:08:38,672] {stage_redshift.py:63} INFO - Start implementation of StageToRedshiftOperator
[2021-04-26 09:08:38,672] {stage_redshift.py:68} INFO - Preparing destination Redshift table
[2021-04-26 09:08:38,715] {base.py:78} INFO - Using connection to: id: redshift. Host: redshift.cxvwoeu3kuea.us-west-2.redshift.amazonaws.com, Port: 5439, Schema: dev, Login: awsuser, Password: XXXXXXXX, extra: None
[2021-04-26 09:08:40,242] {dbapi.py:180} INFO - Running statement: DELETE FROM staging_events, parameters: None
[2021-04-26 09:08:40,838] {dbapi.py:186} INFO - Rows affected: 0
[2021-04-26 09:08:41,144] {stage_redshift.py:71} INFO - Getting data from S3 to Redshift
[2021-04-26 09:08:41,475] {base.py:78} INFO - Using connection to: id: redshift. Host: redshift.cxvwoeu3kuea.us-west-2.redshift.amazonaws.com, Port: 5439, Schema: dev, Login: awsuser, Password: XXXXXXXX, extra: None
[2021-04-26 09:08:42,938] {dbapi.py:180} INFO - Running statement: 
             COPY staging_events 
             FROM 's3://udacity-dend/log_data/2018/11/*'
             FORMAT AS JSON 'log_json_path.json'
             CREDENTIALS
             'aws_access_key_id=None;aws_secret_access_key=None'
                , parameters: None
[2021-04-26 09:08:43,510] {taskinstance.py:1482} ERROR - Task failed with exception
Traceback (most recent call last):
  File "/home/airflow/.local/lib/python3.6/site-packages/airflow/models/taskinstance.py", line 1138, in _run_raw_task
    self._prepare_and_execute_task_with_callbacks(context, task)
  File "/home/airflow/.local/lib/python3.6/site-packages/airflow/models/taskinstance.py", line 1311, in _prepare_and_execute_task_with_callbacks
    result = self._execute_task(context, task_copy)
  File "/home/airflow/.local/lib/python3.6/site-packages/airflow/models/taskinstance.py", line 1341, in _execute_task
    result = task_copy.execute(context=context)
  File "/opt/airflow/plugins/operators/stage_redshift.py", line 81, in execute
    redshift.run(execution_sql)
  File "/home/airflow/.local/lib/python3.6/site-packages/airflow/hooks/dbapi.py", line 184, in run
    cur.execute(sql_statement)
psycopg2.errors.InternalError_: S3ServiceException:The AWS Access Key Id you provided does not exist in our records.,Status 403,Error InvalidAccessKeyId,Rid RB6Q6XHM6HDFWHF8,ExtRid ySQ1NEKjnvOcLJfGAn7BDCtHJgRM5HvnwkIympRpuEj6KeSwNFRc/oTjI6W1xlwYAlamxzGHwOU=,CanRetry 1
DETAIL:  
  -----------------------------------------------
  error:  S3ServiceException:The AWS Access Key Id you provided does not exist in our records.,Status 403,Error InvalidAccessKeyId,Rid RB6Q6XHM6HDFWHF8,ExtRid ySQ1NEKjnvOcLJfGAn7BDCtHJgRM5HvnwkIympRpuEj6KeSwNFRc/oTjI6W1xlwYAlamxzGHwOU=,CanRetry 1
  code:      8001
  context:   Listing bucket=udacity-dend prefix=log_data/2018/11/*
  query:     228
  location:  s3_utility.cpp:654
  process:   padbmaster [pid=13905]
  -----------------------------------------------


[2021-04-26 09:08:43,655] {taskinstance.py:1532} INFO - Marking task as UP_FOR_RETRY. dag_id=project_dag, task_id=Stage_events, execution_date=20210101T000000, start_date=20210426T090832, end_date=20210426T090843
[2021-04-26 09:08:45,549] {local_task_job.py:146} INFO - Task exited with return code 1
[2021-04-26 12:36:09,395] {taskinstance.py:877} INFO - Dependencies all met for <TaskInstance: project_dag.Stage_events 2021-01-01T00:00:00+00:00 [queued]>
[2021-04-26 12:36:10,975] {taskinstance.py:877} INFO - Dependencies all met for <TaskInstance: project_dag.Stage_events 2021-01-01T00:00:00+00:00 [queued]>
[2021-04-26 12:36:11,271] {taskinstance.py:1068} INFO - 
--------------------------------------------------------------------------------
[2021-04-26 12:36:11,271] {taskinstance.py:1069} INFO - Starting attempt 1 of 2
[2021-04-26 12:36:11,271] {taskinstance.py:1070} INFO - 
--------------------------------------------------------------------------------
[2021-04-26 12:36:12,224] {taskinstance.py:1089} INFO - Executing <Task(StageToRedshiftOperator): Stage_events> on 2021-01-01T00:00:00+00:00
[2021-04-26 12:36:12,325] {standard_task_runner.py:52} INFO - Started process 112 to run task
[2021-04-26 12:36:12,380] {standard_task_runner.py:76} INFO - Running: ['airflow', 'tasks', 'run', 'project_dag', 'Stage_events', '2021-01-01T00:00:00+00:00', '--job-id', '30', '--pool', 'default_pool', '--raw', '--subdir', 'DAGS_FOLDER/udac_example_dag.py', '--cfg-path', '/tmp/tmpgdggrpve', '--error-file', '/tmp/tmpcqlmyf_3']
[2021-04-26 12:36:12,437] {standard_task_runner.py:77} INFO - Job 30: Subtask Stage_events
[2021-04-26 12:36:14,135] {logging_mixin.py:104} INFO - Running <TaskInstance: project_dag.Stage_events 2021-01-01T00:00:00+00:00 [running]> on host 0f1e1da1f4f6
[2021-04-26 12:36:19,831] {taskinstance.py:1283} INFO - Exporting the following env vars:
AIRFLOW_CTX_DAG_EMAIL=ernestoffor@gmail.com.com
AIRFLOW_CTX_DAG_OWNER=udacity
AIRFLOW_CTX_DAG_ID=project_dag
AIRFLOW_CTX_TASK_ID=Stage_events
AIRFLOW_CTX_EXECUTION_DATE=2021-01-01T00:00:00+00:00
AIRFLOW_CTX_DAG_RUN_ID=scheduled__2021-01-01T00:00:00+00:00
[2021-04-26 12:36:19,832] {stage_redshift.py:62} INFO - Start implementation of StageToRedshiftOperator
[2021-04-26 12:36:19,832] {stage_redshift.py:67} INFO - Preparing destination Redshift table
[2021-04-26 12:36:19,970] {base.py:78} INFO - Using connection to: id: redshift. Host: redshift.cxvwoeu3kuea.us-west-2.redshift.amazonaws.com, Port: 5439, Schema: dev, Login: awsuser, Password: XXXXXXXX, extra: None
[2021-04-26 12:36:21,401] {dbapi.py:180} INFO - Running statement: DELETE FROM staging_events, parameters: None
[2021-04-26 12:36:22,094] {dbapi.py:186} INFO - Rows affected: 0
[2021-04-26 12:36:22,388] {stage_redshift.py:70} INFO - Getting data from S3 to Redshift
[2021-04-26 12:36:22,567] {base.py:78} INFO - Using connection to: id: redshift. Host: redshift.cxvwoeu3kuea.us-west-2.redshift.amazonaws.com, Port: 5439, Schema: dev, Login: awsuser, Password: XXXXXXXX, extra: None
[2021-04-26 12:36:24,067] {dbapi.py:180} INFO - Running statement: 
             COPY staging_events 
             FROM '/offor_data/log_data/2018/11/*'
             FORMAT AS JSON 'log_json_path.json'
                  , parameters: None
[2021-04-26 12:36:24,470] {taskinstance.py:1482} ERROR - Task failed with exception
Traceback (most recent call last):
  File "/home/airflow/.local/lib/python3.6/site-packages/airflow/models/taskinstance.py", line 1138, in _run_raw_task
    self._prepare_and_execute_task_with_callbacks(context, task)
  File "/home/airflow/.local/lib/python3.6/site-packages/airflow/models/taskinstance.py", line 1311, in _prepare_and_execute_task_with_callbacks
    result = self._execute_task(context, task_copy)
  File "/home/airflow/.local/lib/python3.6/site-packages/airflow/models/taskinstance.py", line 1341, in _execute_task
    result = task_copy.execute(context=context)
  File "/opt/airflow/plugins/operators/stage_redshift.py", line 80, in execute
    redshift.run(execution_sql)
  File "/home/airflow/.local/lib/python3.6/site-packages/airflow/hooks/dbapi.py", line 184, in run
    cur.execute(sql_statement)
psycopg2.errors.InternalError_: LOAD source is not supported. (Hint: only S3 or DynamoDB or EMR based load is allowed)

[2021-04-26 12:36:24,525] {taskinstance.py:1532} INFO - Marking task as UP_FOR_RETRY. dag_id=project_dag, task_id=Stage_events, execution_date=20210101T000000, start_date=20210426T123609, end_date=20210426T123624
[2021-04-26 12:36:25,465] {local_task_job.py:146} INFO - Task exited with return code 1
[2021-04-27 19:21:45,266] {taskinstance.py:877} INFO - Dependencies all met for <TaskInstance: project_dag.Stage_events 2021-01-01T00:00:00+00:00 [queued]>
[2021-04-27 19:21:45,378] {taskinstance.py:877} INFO - Dependencies all met for <TaskInstance: project_dag.Stage_events 2021-01-01T00:00:00+00:00 [queued]>
[2021-04-27 19:21:45,384] {taskinstance.py:1068} INFO - 
--------------------------------------------------------------------------------
[2021-04-27 19:21:45,386] {taskinstance.py:1069} INFO - Starting attempt 1 of 2
[2021-04-27 19:21:45,387] {taskinstance.py:1070} INFO - 
--------------------------------------------------------------------------------
[2021-04-27 19:21:45,461] {taskinstance.py:1089} INFO - Executing <Task(StageToRedshiftOperator): Stage_events> on 2021-01-01T00:00:00+00:00
[2021-04-27 19:21:45,527] {standard_task_runner.py:76} INFO - Running: ['airflow', 'tasks', 'run', 'project_dag', 'Stage_events', '2021-01-01T00:00:00+00:00', '--job-id', '64', '--pool', 'default_pool', '--raw', '--subdir', 'DAGS_FOLDER/udac_example_dag.py', '--cfg-path', '/tmp/tmpzliq8m4a', '--error-file', '/tmp/tmpneev_ssh']
[2021-04-27 19:21:45,529] {standard_task_runner.py:77} INFO - Job 64: Subtask Stage_events
[2021-04-27 19:21:45,497] {standard_task_runner.py:52} INFO - Started process 44 to run task
[2021-04-27 19:21:45,947] {logging_mixin.py:104} INFO - Running <TaskInstance: project_dag.Stage_events 2021-01-01T00:00:00+00:00 [running]> on host 0f1e1da1f4f6
[2021-04-27 19:21:46,937] {taskinstance.py:1283} INFO - Exporting the following env vars:
AIRFLOW_CTX_DAG_EMAIL=ernestoffor@gmail.com.com
AIRFLOW_CTX_DAG_OWNER=udacity
AIRFLOW_CTX_DAG_ID=project_dag
AIRFLOW_CTX_TASK_ID=Stage_events
AIRFLOW_CTX_EXECUTION_DATE=2021-01-01T00:00:00+00:00
AIRFLOW_CTX_DAG_RUN_ID=scheduled__2021-01-01T00:00:00+00:00
[2021-04-27 19:21:46,938] {stage_redshift.py:65} INFO - Start implementation of StageToRedshiftOperator
[2021-04-27 19:21:46,939] {taskinstance.py:1482} ERROR - Task failed with exception
Traceback (most recent call last):
  File "/home/airflow/.local/lib/python3.6/site-packages/airflow/models/taskinstance.py", line 1138, in _run_raw_task
    self._prepare_and_execute_task_with_callbacks(context, task)
  File "/home/airflow/.local/lib/python3.6/site-packages/airflow/models/taskinstance.py", line 1311, in _prepare_and_execute_task_with_callbacks
    result = self._execute_task(context, task_copy)
  File "/home/airflow/.local/lib/python3.6/site-packages/airflow/models/taskinstance.py", line 1341, in _execute_task
    result = task_copy.execute(context=context)
  File "/opt/airflow/plugins/operators/stage_redshift.py", line 66, in execute
    s3 = S3hook(aws_conn_id=self.aws_credentials_id)
NameError: name 'S3hook' is not defined
[2021-04-27 19:21:47,098] {taskinstance.py:1532} INFO - Marking task as UP_FOR_RETRY. dag_id=project_dag, task_id=Stage_events, execution_date=20210101T000000, start_date=20210427T192145, end_date=20210427T192147
[2021-04-27 19:21:47,576] {local_task_job.py:146} INFO - Task exited with return code 1
[2021-04-27 20:40:32,452] {taskinstance.py:877} INFO - Dependencies all met for <TaskInstance: project_dag.Stage_events 2021-01-01T00:00:00+00:00 [queued]>
[2021-04-27 20:40:32,719] {taskinstance.py:877} INFO - Dependencies all met for <TaskInstance: project_dag.Stage_events 2021-01-01T00:00:00+00:00 [queued]>
[2021-04-27 20:40:32,719] {taskinstance.py:1068} INFO - 
--------------------------------------------------------------------------------
[2021-04-27 20:40:32,719] {taskinstance.py:1069} INFO - Starting attempt 1 of 2
[2021-04-27 20:40:32,719] {taskinstance.py:1070} INFO - 
--------------------------------------------------------------------------------
[2021-04-27 20:40:32,875] {taskinstance.py:1089} INFO - Executing <Task(StageToRedshiftOperator): Stage_events> on 2021-01-01T00:00:00+00:00
[2021-04-27 20:40:32,917] {standard_task_runner.py:52} INFO - Started process 252 to run task
[2021-04-27 20:40:32,998] {standard_task_runner.py:76} INFO - Running: ['airflow', 'tasks', 'run', 'project_dag', 'Stage_events', '2021-01-01T00:00:00+00:00', '--job-id', '107', '--pool', 'default_pool', '--raw', '--subdir', 'DAGS_FOLDER/udac_example_dag.py', '--cfg-path', '/tmp/tmpp4qgsozg', '--error-file', '/tmp/tmp7fga40se']
[2021-04-27 20:40:32,999] {standard_task_runner.py:77} INFO - Job 107: Subtask Stage_events
[2021-04-27 20:40:33,630] {logging_mixin.py:104} INFO - Running <TaskInstance: project_dag.Stage_events 2021-01-01T00:00:00+00:00 [running]> on host 478c7ec349b0
[2021-04-27 20:40:34,698] {taskinstance.py:1283} INFO - Exporting the following env vars:
AIRFLOW_CTX_DAG_EMAIL=ernestoffor@gmail.com.com
AIRFLOW_CTX_DAG_OWNER=udacity
AIRFLOW_CTX_DAG_ID=project_dag
AIRFLOW_CTX_TASK_ID=Stage_events
AIRFLOW_CTX_EXECUTION_DATE=2021-01-01T00:00:00+00:00
AIRFLOW_CTX_DAG_RUN_ID=scheduled__2021-01-01T00:00:00+00:00
[2021-04-27 20:40:34,709] {stage_redshift.py:67} INFO - Start implementation of StageToRedshiftOperator
[2021-04-27 20:40:34,716] {stage_redshift.py:74} INFO - Preparing destination Redshift table
[2021-04-27 20:40:34,969] {base.py:78} INFO - Using connection to: id: redshift. Host: redshift.cxvwoeu3kuea.us-west-2.redshift.amazonaws.com, Port: 5439, Schema: dev, Login: awsuser, Password: XXXXXXXX, extra: None
[2021-04-27 20:40:36,460] {dbapi.py:180} INFO - Running statement: DELETE FROM staging_events, parameters: None
[2021-04-27 20:40:36,903] {dbapi.py:186} INFO - Rows affected: 0
[2021-04-27 20:40:37,306] {stage_redshift.py:77} INFO - Getting data from S3 to Redshift
[2021-04-27 20:40:39,560] {taskinstance.py:1482} ERROR - Task failed with exception
Traceback (most recent call last):
  File "/home/airflow/.local/lib/python3.6/site-packages/airflow/models/taskinstance.py", line 1138, in _run_raw_task
    self._prepare_and_execute_task_with_callbacks(context, task)
  File "/home/airflow/.local/lib/python3.6/site-packages/airflow/models/taskinstance.py", line 1311, in _prepare_and_execute_task_with_callbacks
    result = self._execute_task(context, task_copy)
  File "/home/airflow/.local/lib/python3.6/site-packages/airflow/models/taskinstance.py", line 1341, in _execute_task
    result = task_copy.execute(context=context)
  File "/opt/airflow/plugins/operators/stage_redshift.py", line 83, in execute
    s3.get_credentials().access_key,
  File "/home/airflow/.local/lib/python3.6/site-packages/airflow/providers/amazon/aws/hooks/base_aws.py", line 478, in get_credentials
    return session.get_credentials().get_frozen_credentials()
AttributeError: 'NoneType' object has no attribute 'get_frozen_credentials'
[2021-04-27 20:40:39,576] {taskinstance.py:1532} INFO - Marking task as UP_FOR_RETRY. dag_id=project_dag, task_id=Stage_events, execution_date=20210101T000000, start_date=20210427T204032, end_date=20210427T204039
[2021-04-27 20:40:39,730] {local_task_job.py:146} INFO - Task exited with return code 1
