[2021-04-24 11:50:35,372] {taskinstance.py:877} INFO - Dependencies all met for <TaskInstance: project_dag.Stage_events 2020-07-01T00:00:00+00:00 [queued]>
[2021-04-24 11:50:35,512] {taskinstance.py:877} INFO - Dependencies all met for <TaskInstance: project_dag.Stage_events 2020-07-01T00:00:00+00:00 [queued]>
[2021-04-24 11:50:35,518] {taskinstance.py:1068} INFO - 
--------------------------------------------------------------------------------
[2021-04-24 11:50:35,526] {taskinstance.py:1069} INFO - Starting attempt 2 of 2
[2021-04-24 11:50:35,526] {taskinstance.py:1070} INFO - 
--------------------------------------------------------------------------------
[2021-04-24 11:50:35,731] {taskinstance.py:1089} INFO - Executing <Task(StageToRedshiftOperator): Stage_events> on 2020-07-01T00:00:00+00:00
[2021-04-24 11:50:35,754] {standard_task_runner.py:52} INFO - Started process 267 to run task
[2021-04-24 11:50:35,820] {standard_task_runner.py:76} INFO - Running: ['airflow', 'tasks', 'run', 'project_dag', 'Stage_events', '2020-07-01T00:00:00+00:00', '--job-id', '116', '--pool', 'default_pool', '--raw', '--subdir', 'DAGS_FOLDER/udac_example_dag.py', '--cfg-path', '/tmp/tmpcrx253f3', '--error-file', '/tmp/tmp9_89mssk']
[2021-04-24 11:50:35,831] {standard_task_runner.py:77} INFO - Job 116: Subtask Stage_events
[2021-04-24 11:50:36,556] {logging_mixin.py:104} INFO - Running <TaskInstance: project_dag.Stage_events 2020-07-01T00:00:00+00:00 [running]> on host 88dcd2a12842
[2021-04-24 11:50:37,001] {taskinstance.py:1283} INFO - Exporting the following env vars:
AIRFLOW_CTX_DAG_EMAIL=ernest@gmail.com.com
AIRFLOW_CTX_DAG_OWNER=udacity
AIRFLOW_CTX_DAG_ID=project_dag
AIRFLOW_CTX_TASK_ID=Stage_events
AIRFLOW_CTX_EXECUTION_DATE=2020-07-01T00:00:00+00:00
AIRFLOW_CTX_DAG_RUN_ID=scheduled__2020-07-01T00:00:00+00:00
[2021-04-24 11:50:37,013] {stage_redshift.py:38} INFO - Start implementation of StageToRedshiftOperator
[2021-04-24 11:50:37,091] {taskinstance.py:1482} ERROR - Task failed with exception
Traceback (most recent call last):
  File "/home/airflow/.local/lib/python3.6/site-packages/airflow/models/taskinstance.py", line 1138, in _run_raw_task
    self._prepare_and_execute_task_with_callbacks(context, task)
  File "/home/airflow/.local/lib/python3.6/site-packages/airflow/models/taskinstance.py", line 1311, in _prepare_and_execute_task_with_callbacks
    result = self._execute_task(context, task_copy)
  File "/home/airflow/.local/lib/python3.6/site-packages/airflow/models/taskinstance.py", line 1341, in _execute_task
    result = task_copy.execute(context=context)
  File "/opt/airflow/plugins/operators/stage_redshift.py", line 39, in execute
    aws_hook = AwsHook(self.aws_credentials_id)
  File "/home/airflow/.local/lib/python3.6/site-packages/airflow/contrib/hooks/aws_hook.py", line 41, in __init__
    super().__init__(*args, **kwargs)
  File "/home/airflow/.local/lib/python3.6/site-packages/airflow/providers/amazon/aws/hooks/base_aws.py", line 360, in __init__
    raise AirflowException('Either client_type or resource_type must be provided.')
airflow.exceptions.AirflowException: Either client_type or resource_type must be provided.
[2021-04-24 11:50:37,103] {taskinstance.py:1532} INFO - Marking task as FAILED. dag_id=project_dag, task_id=Stage_events, execution_date=20200701T000000, start_date=20210424T115035, end_date=20210424T115037
[2021-04-24 11:50:37,323] {configuration.py:352} WARNING - section/key [smtp/smtp_user] not found in config
[2021-04-24 11:50:37,363] {email.py:184} INFO - Email alerting: attempt 1
[2021-04-24 11:50:37,378] {configuration.py:352} WARNING - section/key [smtp/smtp_user] not found in config
[2021-04-24 11:50:37,380] {email.py:184} INFO - Email alerting: attempt 1
[2021-04-24 11:50:37,383] {taskinstance.py:1538} ERROR - Failed to send email to: ['ernest@gmail.com.com']
[2021-04-24 11:50:37,385] {taskinstance.py:1539} ERROR - [Errno 99] Cannot assign requested address
Traceback (most recent call last):
  File "/home/airflow/.local/lib/python3.6/site-packages/airflow/models/taskinstance.py", line 1138, in _run_raw_task
    self._prepare_and_execute_task_with_callbacks(context, task)
  File "/home/airflow/.local/lib/python3.6/site-packages/airflow/models/taskinstance.py", line 1311, in _prepare_and_execute_task_with_callbacks
    result = self._execute_task(context, task_copy)
  File "/home/airflow/.local/lib/python3.6/site-packages/airflow/models/taskinstance.py", line 1341, in _execute_task
    result = task_copy.execute(context=context)
  File "/opt/airflow/plugins/operators/stage_redshift.py", line 39, in execute
    aws_hook = AwsHook(self.aws_credentials_id)
  File "/home/airflow/.local/lib/python3.6/site-packages/airflow/contrib/hooks/aws_hook.py", line 41, in __init__
    super().__init__(*args, **kwargs)
  File "/home/airflow/.local/lib/python3.6/site-packages/airflow/providers/amazon/aws/hooks/base_aws.py", line 360, in __init__
    raise AirflowException('Either client_type or resource_type must be provided.')
airflow.exceptions.AirflowException: Either client_type or resource_type must be provided.

During handling of the above exception, another exception occurred:

Traceback (most recent call last):
  File "/home/airflow/.local/lib/python3.6/site-packages/airflow/models/taskinstance.py", line 1881, in email_alert
    send_email(self.task.email, subject, html_content)
  File "/home/airflow/.local/lib/python3.6/site-packages/airflow/utils/email.py", line 62, in send_email
    **kwargs,
  File "/home/airflow/.local/lib/python3.6/site-packages/airflow/utils/email.py", line 97, in send_email_smtp
    send_mime_email(e_from=smtp_mail_from, e_to=recipients, mime_msg=msg, dryrun=dryrun)
  File "/home/airflow/.local/lib/python3.6/site-packages/airflow/utils/email.py", line 186, in send_mime_email
    conn = _get_smtp_connection(smtp_host, smtp_port, smtp_timeout, smtp_ssl)
  File "/home/airflow/.local/lib/python3.6/site-packages/airflow/utils/email.py", line 220, in _get_smtp_connection
    else smtplib.SMTP(host=host, port=port, timeout=timeout)
  File "/usr/local/lib/python3.6/smtplib.py", line 251, in __init__
    (code, msg) = self.connect(host, port)
  File "/usr/local/lib/python3.6/smtplib.py", line 336, in connect
    self.sock = self._get_socket(host, port, self.timeout)
  File "/usr/local/lib/python3.6/smtplib.py", line 307, in _get_socket
    self.source_address)
  File "/usr/local/lib/python3.6/socket.py", line 724, in create_connection
    raise err
  File "/usr/local/lib/python3.6/socket.py", line 713, in create_connection
    sock.connect(sa)
OSError: [Errno 99] Cannot assign requested address

During handling of the above exception, another exception occurred:

Traceback (most recent call last):
  File "/home/airflow/.local/lib/python3.6/site-packages/airflow/models/taskinstance.py", line 1536, in handle_failure
    self.email_alert(error)
  File "/home/airflow/.local/lib/python3.6/site-packages/airflow/models/taskinstance.py", line 1883, in email_alert
    send_email(self.task.email, subject, html_content_err)
  File "/home/airflow/.local/lib/python3.6/site-packages/airflow/utils/email.py", line 62, in send_email
    **kwargs,
  File "/home/airflow/.local/lib/python3.6/site-packages/airflow/utils/email.py", line 97, in send_email_smtp
    send_mime_email(e_from=smtp_mail_from, e_to=recipients, mime_msg=msg, dryrun=dryrun)
  File "/home/airflow/.local/lib/python3.6/site-packages/airflow/utils/email.py", line 186, in send_mime_email
    conn = _get_smtp_connection(smtp_host, smtp_port, smtp_timeout, smtp_ssl)
  File "/home/airflow/.local/lib/python3.6/site-packages/airflow/utils/email.py", line 220, in _get_smtp_connection
    else smtplib.SMTP(host=host, port=port, timeout=timeout)
  File "/usr/local/lib/python3.6/smtplib.py", line 251, in __init__
    (code, msg) = self.connect(host, port)
  File "/usr/local/lib/python3.6/smtplib.py", line 336, in connect
    self.sock = self._get_socket(host, port, self.timeout)
  File "/usr/local/lib/python3.6/smtplib.py", line 307, in _get_socket
    self.source_address)
  File "/usr/local/lib/python3.6/socket.py", line 724, in create_connection
    raise err
  File "/usr/local/lib/python3.6/socket.py", line 713, in create_connection
    sock.connect(sa)
OSError: [Errno 99] Cannot assign requested address
[2021-04-24 11:50:37,502] {local_task_job.py:146} INFO - Task exited with return code 1
[2021-04-26 09:14:08,432] {taskinstance.py:877} INFO - Dependencies all met for <TaskInstance: project_dag.Stage_events 2020-07-01T00:00:00+00:00 [queued]>
[2021-04-26 09:14:08,851] {taskinstance.py:877} INFO - Dependencies all met for <TaskInstance: project_dag.Stage_events 2020-07-01T00:00:00+00:00 [queued]>
[2021-04-26 09:14:08,852] {taskinstance.py:1068} INFO - 
--------------------------------------------------------------------------------
[2021-04-26 09:14:08,852] {taskinstance.py:1069} INFO - Starting attempt 2 of 2
[2021-04-26 09:14:08,852] {taskinstance.py:1070} INFO - 
--------------------------------------------------------------------------------
[2021-04-26 09:14:09,075] {taskinstance.py:1089} INFO - Executing <Task(StageToRedshiftOperator): Stage_events> on 2020-07-01T00:00:00+00:00
[2021-04-26 09:14:09,190] {standard_task_runner.py:52} INFO - Started process 165 to run task
[2021-04-26 09:14:09,314] {standard_task_runner.py:76} INFO - Running: ['airflow', 'tasks', 'run', 'project_dag', 'Stage_events', '2020-07-01T00:00:00+00:00', '--job-id', '59', '--pool', 'default_pool', '--raw', '--subdir', 'DAGS_FOLDER/udac_example_dag.py', '--cfg-path', '/tmp/tmprzeu29pw', '--error-file', '/tmp/tmpkqss_ydw']
[2021-04-26 09:14:09,326] {standard_task_runner.py:77} INFO - Job 59: Subtask Stage_events
[2021-04-26 09:14:10,110] {logging_mixin.py:104} INFO - Running <TaskInstance: project_dag.Stage_events 2020-07-01T00:00:00+00:00 [running]> on host b5c40a6f08c7
[2021-04-26 09:14:10,635] {taskinstance.py:1283} INFO - Exporting the following env vars:
AIRFLOW_CTX_DAG_EMAIL=ernestoffor@gmail.com.com
AIRFLOW_CTX_DAG_OWNER=udacity
AIRFLOW_CTX_DAG_ID=project_dag
AIRFLOW_CTX_TASK_ID=Stage_events
AIRFLOW_CTX_EXECUTION_DATE=2020-07-01T00:00:00+00:00
AIRFLOW_CTX_DAG_RUN_ID=scheduled__2020-07-01T00:00:00+00:00
[2021-04-26 09:14:10,637] {stage_redshift.py:63} INFO - Start implementation of StageToRedshiftOperator
[2021-04-26 09:14:10,637] {stage_redshift.py:68} INFO - Preparing destination Redshift table
[2021-04-26 09:14:10,891] {base.py:78} INFO - Using connection to: id: redshift. Host: redshift.cxvwoeu3kuea.us-west-2.redshift.amazonaws.com, Port: 5439, Schema: dev, Login: awsuser, Password: XXXXXXXX, extra: None
[2021-04-26 09:14:12,453] {dbapi.py:180} INFO - Running statement: DELETE FROM staging_events, parameters: None
[2021-04-26 09:14:12,893] {dbapi.py:186} INFO - Rows affected: 0
[2021-04-26 09:14:13,192] {stage_redshift.py:71} INFO - Getting data from S3 to Redshift
[2021-04-26 09:14:13,235] {base.py:78} INFO - Using connection to: id: redshift. Host: redshift.cxvwoeu3kuea.us-west-2.redshift.amazonaws.com, Port: 5439, Schema: dev, Login: awsuser, Password: XXXXXXXX, extra: None
[2021-04-26 09:14:14,769] {dbapi.py:180} INFO - Running statement: 
             COPY staging_events 
             FROM 's3://udacity-dend/log_data/2018/11/*'
             FORMAT AS JSON 'log_json_path.json'
             CREDENTIALS
             'aws_access_key_id=None;aws_secret_access_key=None'
                , parameters: None
[2021-04-26 09:14:15,365] {taskinstance.py:1482} ERROR - Task failed with exception
Traceback (most recent call last):
  File "/home/airflow/.local/lib/python3.6/site-packages/airflow/models/taskinstance.py", line 1138, in _run_raw_task
    self._prepare_and_execute_task_with_callbacks(context, task)
  File "/home/airflow/.local/lib/python3.6/site-packages/airflow/models/taskinstance.py", line 1311, in _prepare_and_execute_task_with_callbacks
    result = self._execute_task(context, task_copy)
  File "/home/airflow/.local/lib/python3.6/site-packages/airflow/models/taskinstance.py", line 1341, in _execute_task
    result = task_copy.execute(context=context)
  File "/opt/airflow/plugins/operators/stage_redshift.py", line 81, in execute
    redshift.run(execution_sql)
  File "/home/airflow/.local/lib/python3.6/site-packages/airflow/hooks/dbapi.py", line 184, in run
    cur.execute(sql_statement)
psycopg2.errors.InternalError_: S3ServiceException:The AWS Access Key Id you provided does not exist in our records.,Status 403,Error InvalidAccessKeyId,Rid 1NA4TNX78VSJR4E3,ExtRid fUfPjEVJ7uhcE9pzHEH4FJDeEsvP26ih1lM/zLfJLXIhbNdIu3F6q1jZcXJMJShYokLJd6c4lqc=,CanRetry 1
DETAIL:  
  -----------------------------------------------
  error:  S3ServiceException:The AWS Access Key Id you provided does not exist in our records.,Status 403,Error InvalidAccessKeyId,Rid 1NA4TNX78VSJR4E3,ExtRid fUfPjEVJ7uhcE9pzHEH4FJDeEsvP26ih1lM/zLfJLXIhbNdIu3F6q1jZcXJMJShYokLJd6c4lqc=,CanRetry 1
  code:      8001
  context:   Listing bucket=udacity-dend prefix=log_data/2018/11/*
  query:     361
  location:  s3_utility.cpp:654
  process:   padbmaster [pid=15451]
  -----------------------------------------------


[2021-04-26 09:14:15,392] {taskinstance.py:1532} INFO - Marking task as FAILED. dag_id=project_dag, task_id=Stage_events, execution_date=20200701T000000, start_date=20210426T091408, end_date=20210426T091415
[2021-04-26 09:14:15,963] {local_task_job.py:146} INFO - Task exited with return code 1
[2021-04-26 12:40:58,942] {taskinstance.py:877} INFO - Dependencies all met for <TaskInstance: project_dag.Stage_events 2020-07-01T00:00:00+00:00 [queued]>
[2021-04-26 12:40:59,154] {taskinstance.py:877} INFO - Dependencies all met for <TaskInstance: project_dag.Stage_events 2020-07-01T00:00:00+00:00 [queued]>
[2021-04-26 12:40:59,160] {taskinstance.py:1068} INFO - 
--------------------------------------------------------------------------------
[2021-04-26 12:40:59,161] {taskinstance.py:1069} INFO - Starting attempt 2 of 2
[2021-04-26 12:40:59,161] {taskinstance.py:1070} INFO - 
--------------------------------------------------------------------------------
[2021-04-26 12:40:59,282] {taskinstance.py:1089} INFO - Executing <Task(StageToRedshiftOperator): Stage_events> on 2020-07-01T00:00:00+00:00
[2021-04-26 12:40:59,333] {standard_task_runner.py:52} INFO - Started process 136 to run task
[2021-04-26 12:40:59,455] {standard_task_runner.py:76} INFO - Running: ['airflow', 'tasks', 'run', 'project_dag', 'Stage_events', '2020-07-01T00:00:00+00:00', '--job-id', '43', '--pool', 'default_pool', '--raw', '--subdir', 'DAGS_FOLDER/udac_example_dag.py', '--cfg-path', '/tmp/tmpp353wg4c', '--error-file', '/tmp/tmpibh7k6xx']
[2021-04-26 12:40:59,456] {standard_task_runner.py:77} INFO - Job 43: Subtask Stage_events
[2021-04-26 12:41:00,248] {logging_mixin.py:104} INFO - Running <TaskInstance: project_dag.Stage_events 2020-07-01T00:00:00+00:00 [running]> on host 0f1e1da1f4f6
[2021-04-26 12:41:00,760] {taskinstance.py:1283} INFO - Exporting the following env vars:
AIRFLOW_CTX_DAG_EMAIL=ernestoffor@gmail.com.com
AIRFLOW_CTX_DAG_OWNER=udacity
AIRFLOW_CTX_DAG_ID=project_dag
AIRFLOW_CTX_TASK_ID=Stage_events
AIRFLOW_CTX_EXECUTION_DATE=2020-07-01T00:00:00+00:00
AIRFLOW_CTX_DAG_RUN_ID=scheduled__2020-07-01T00:00:00+00:00
[2021-04-26 12:41:00,761] {stage_redshift.py:62} INFO - Start implementation of StageToRedshiftOperator
[2021-04-26 12:41:00,761] {stage_redshift.py:67} INFO - Preparing destination Redshift table
[2021-04-26 12:41:00,841] {base.py:78} INFO - Using connection to: id: redshift. Host: redshift.cxvwoeu3kuea.us-west-2.redshift.amazonaws.com, Port: 5439, Schema: dev, Login: awsuser, Password: XXXXXXXX, extra: None
[2021-04-26 12:41:00,875] {taskinstance.py:1482} ERROR - Task failed with exception
Traceback (most recent call last):
  File "/home/airflow/.local/lib/python3.6/site-packages/airflow/models/taskinstance.py", line 1138, in _run_raw_task
    self._prepare_and_execute_task_with_callbacks(context, task)
  File "/home/airflow/.local/lib/python3.6/site-packages/airflow/models/taskinstance.py", line 1311, in _prepare_and_execute_task_with_callbacks
    result = self._execute_task(context, task_copy)
  File "/home/airflow/.local/lib/python3.6/site-packages/airflow/models/taskinstance.py", line 1341, in _execute_task
    result = task_copy.execute(context=context)
  File "/opt/airflow/plugins/operators/stage_redshift.py", line 68, in execute
    redshift.run("DELETE FROM {}".format(self.staging_table))
  File "/home/airflow/.local/lib/python3.6/site-packages/airflow/hooks/dbapi.py", line 173, in run
    with closing(self.get_conn()) as conn:
  File "/home/airflow/.local/lib/python3.6/site-packages/airflow/providers/postgres/hooks/postgres.py", line 108, in get_conn
    self.conn = psycopg2.connect(**conn_args)
  File "/home/airflow/.local/lib/python3.6/site-packages/psycopg2/__init__.py", line 127, in connect
    conn = _connect(dsn, connection_factory=connection_factory, **kwasync)
psycopg2.OperationalError: could not translate host name "redshift.cxvwoeu3kuea.us-west-2.redshift.amazonaws.com" to address: Name or service not known

[2021-04-26 12:41:00,886] {taskinstance.py:1532} INFO - Marking task as FAILED. dag_id=project_dag, task_id=Stage_events, execution_date=20200701T000000, start_date=20210426T124058, end_date=20210426T124100
[2021-04-26 12:41:01,084] {local_task_job.py:146} INFO - Task exited with return code 1
