[2021-04-24 11:50:38,859] {taskinstance.py:877} INFO - Dependencies all met for <TaskInstance: project_dag.Stage_events 2020-06-01T00:00:00+00:00 [queued]>
[2021-04-24 11:50:38,967] {taskinstance.py:877} INFO - Dependencies all met for <TaskInstance: project_dag.Stage_events 2020-06-01T00:00:00+00:00 [queued]>
[2021-04-24 11:50:38,968] {taskinstance.py:1068} INFO - 
--------------------------------------------------------------------------------
[2021-04-24 11:50:38,970] {taskinstance.py:1069} INFO - Starting attempt 2 of 2
[2021-04-24 11:50:38,971] {taskinstance.py:1070} INFO - 
--------------------------------------------------------------------------------
[2021-04-24 11:50:39,035] {taskinstance.py:1089} INFO - Executing <Task(StageToRedshiftOperator): Stage_events> on 2020-06-01T00:00:00+00:00
[2021-04-24 11:50:39,062] {standard_task_runner.py:76} INFO - Running: ['airflow', 'tasks', 'run', 'project_dag', 'Stage_events', '2020-06-01T00:00:00+00:00', '--job-id', '118', '--pool', 'default_pool', '--raw', '--subdir', 'DAGS_FOLDER/udac_example_dag.py', '--cfg-path', '/tmp/tmpnaxslo2a', '--error-file', '/tmp/tmpic4y3160']
[2021-04-24 11:50:39,050] {standard_task_runner.py:52} INFO - Started process 274 to run task
[2021-04-24 11:50:39,070] {standard_task_runner.py:77} INFO - Job 118: Subtask Stage_events
[2021-04-24 11:50:39,275] {logging_mixin.py:104} INFO - Running <TaskInstance: project_dag.Stage_events 2020-06-01T00:00:00+00:00 [running]> on host 88dcd2a12842
[2021-04-24 11:50:39,593] {taskinstance.py:1283} INFO - Exporting the following env vars:
AIRFLOW_CTX_DAG_EMAIL=ernest@gmail.com.com
AIRFLOW_CTX_DAG_OWNER=udacity
AIRFLOW_CTX_DAG_ID=project_dag
AIRFLOW_CTX_TASK_ID=Stage_events
AIRFLOW_CTX_EXECUTION_DATE=2020-06-01T00:00:00+00:00
AIRFLOW_CTX_DAG_RUN_ID=scheduled__2020-06-01T00:00:00+00:00
[2021-04-24 11:50:39,595] {stage_redshift.py:38} INFO - Start implementation of StageToRedshiftOperator
[2021-04-24 11:50:39,648] {taskinstance.py:1482} ERROR - Task failed with exception
Traceback (most recent call last):
  File "/home/airflow/.local/lib/python3.6/site-packages/airflow/models/taskinstance.py", line 1138, in _run_raw_task
    self._prepare_and_execute_task_with_callbacks(context, task)
  File "/home/airflow/.local/lib/python3.6/site-packages/airflow/models/taskinstance.py", line 1311, in _prepare_and_execute_task_with_callbacks
    result = self._execute_task(context, task_copy)
  File "/home/airflow/.local/lib/python3.6/site-packages/airflow/models/taskinstance.py", line 1341, in _execute_task
    result = task_copy.execute(context=context)
  File "/opt/airflow/plugins/operators/stage_redshift.py", line 39, in execute
    aws_hook = AwsHook(self.aws_credentials_id)
  File "/home/airflow/.local/lib/python3.6/site-packages/airflow/contrib/hooks/aws_hook.py", line 41, in __init__
    super().__init__(*args, **kwargs)
  File "/home/airflow/.local/lib/python3.6/site-packages/airflow/providers/amazon/aws/hooks/base_aws.py", line 360, in __init__
    raise AirflowException('Either client_type or resource_type must be provided.')
airflow.exceptions.AirflowException: Either client_type or resource_type must be provided.
[2021-04-24 11:50:39,662] {taskinstance.py:1532} INFO - Marking task as FAILED. dag_id=project_dag, task_id=Stage_events, execution_date=20200601T000000, start_date=20210424T115038, end_date=20210424T115039
[2021-04-24 11:50:39,840] {configuration.py:352} WARNING - section/key [smtp/smtp_user] not found in config
[2021-04-24 11:50:39,841] {email.py:184} INFO - Email alerting: attempt 1
[2021-04-24 11:50:39,866] {configuration.py:352} WARNING - section/key [smtp/smtp_user] not found in config
[2021-04-24 11:50:39,867] {email.py:184} INFO - Email alerting: attempt 1
[2021-04-24 11:50:39,868] {taskinstance.py:1538} ERROR - Failed to send email to: ['ernest@gmail.com.com']
[2021-04-24 11:50:39,868] {taskinstance.py:1539} ERROR - [Errno 99] Cannot assign requested address
Traceback (most recent call last):
  File "/home/airflow/.local/lib/python3.6/site-packages/airflow/models/taskinstance.py", line 1138, in _run_raw_task
    self._prepare_and_execute_task_with_callbacks(context, task)
  File "/home/airflow/.local/lib/python3.6/site-packages/airflow/models/taskinstance.py", line 1311, in _prepare_and_execute_task_with_callbacks
    result = self._execute_task(context, task_copy)
  File "/home/airflow/.local/lib/python3.6/site-packages/airflow/models/taskinstance.py", line 1341, in _execute_task
    result = task_copy.execute(context=context)
  File "/opt/airflow/plugins/operators/stage_redshift.py", line 39, in execute
    aws_hook = AwsHook(self.aws_credentials_id)
  File "/home/airflow/.local/lib/python3.6/site-packages/airflow/contrib/hooks/aws_hook.py", line 41, in __init__
    super().__init__(*args, **kwargs)
  File "/home/airflow/.local/lib/python3.6/site-packages/airflow/providers/amazon/aws/hooks/base_aws.py", line 360, in __init__
    raise AirflowException('Either client_type or resource_type must be provided.')
airflow.exceptions.AirflowException: Either client_type or resource_type must be provided.

During handling of the above exception, another exception occurred:

Traceback (most recent call last):
  File "/home/airflow/.local/lib/python3.6/site-packages/airflow/models/taskinstance.py", line 1881, in email_alert
    send_email(self.task.email, subject, html_content)
  File "/home/airflow/.local/lib/python3.6/site-packages/airflow/utils/email.py", line 62, in send_email
    **kwargs,
  File "/home/airflow/.local/lib/python3.6/site-packages/airflow/utils/email.py", line 97, in send_email_smtp
    send_mime_email(e_from=smtp_mail_from, e_to=recipients, mime_msg=msg, dryrun=dryrun)
  File "/home/airflow/.local/lib/python3.6/site-packages/airflow/utils/email.py", line 186, in send_mime_email
    conn = _get_smtp_connection(smtp_host, smtp_port, smtp_timeout, smtp_ssl)
  File "/home/airflow/.local/lib/python3.6/site-packages/airflow/utils/email.py", line 220, in _get_smtp_connection
    else smtplib.SMTP(host=host, port=port, timeout=timeout)
  File "/usr/local/lib/python3.6/smtplib.py", line 251, in __init__
    (code, msg) = self.connect(host, port)
  File "/usr/local/lib/python3.6/smtplib.py", line 336, in connect
    self.sock = self._get_socket(host, port, self.timeout)
  File "/usr/local/lib/python3.6/smtplib.py", line 307, in _get_socket
    self.source_address)
  File "/usr/local/lib/python3.6/socket.py", line 724, in create_connection
    raise err
  File "/usr/local/lib/python3.6/socket.py", line 713, in create_connection
    sock.connect(sa)
OSError: [Errno 99] Cannot assign requested address

During handling of the above exception, another exception occurred:

Traceback (most recent call last):
  File "/home/airflow/.local/lib/python3.6/site-packages/airflow/models/taskinstance.py", line 1536, in handle_failure
    self.email_alert(error)
  File "/home/airflow/.local/lib/python3.6/site-packages/airflow/models/taskinstance.py", line 1883, in email_alert
    send_email(self.task.email, subject, html_content_err)
  File "/home/airflow/.local/lib/python3.6/site-packages/airflow/utils/email.py", line 62, in send_email
    **kwargs,
  File "/home/airflow/.local/lib/python3.6/site-packages/airflow/utils/email.py", line 97, in send_email_smtp
    send_mime_email(e_from=smtp_mail_from, e_to=recipients, mime_msg=msg, dryrun=dryrun)
  File "/home/airflow/.local/lib/python3.6/site-packages/airflow/utils/email.py", line 186, in send_mime_email
    conn = _get_smtp_connection(smtp_host, smtp_port, smtp_timeout, smtp_ssl)
  File "/home/airflow/.local/lib/python3.6/site-packages/airflow/utils/email.py", line 220, in _get_smtp_connection
    else smtplib.SMTP(host=host, port=port, timeout=timeout)
  File "/usr/local/lib/python3.6/smtplib.py", line 251, in __init__
    (code, msg) = self.connect(host, port)
  File "/usr/local/lib/python3.6/smtplib.py", line 336, in connect
    self.sock = self._get_socket(host, port, self.timeout)
  File "/usr/local/lib/python3.6/smtplib.py", line 307, in _get_socket
    self.source_address)
  File "/usr/local/lib/python3.6/socket.py", line 724, in create_connection
    raise err
  File "/usr/local/lib/python3.6/socket.py", line 713, in create_connection
    sock.connect(sa)
OSError: [Errno 99] Cannot assign requested address
[2021-04-24 11:50:40,008] {local_task_job.py:146} INFO - Task exited with return code 1
[2021-04-26 09:13:07,712] {taskinstance.py:877} INFO - Dependencies all met for <TaskInstance: project_dag.Stage_events 2020-06-01T00:00:00+00:00 [queued]>
[2021-04-26 09:13:07,909] {taskinstance.py:877} INFO - Dependencies all met for <TaskInstance: project_dag.Stage_events 2020-06-01T00:00:00+00:00 [queued]>
[2021-04-26 09:13:07,910] {taskinstance.py:1068} INFO - 
--------------------------------------------------------------------------------
[2021-04-26 09:13:07,910] {taskinstance.py:1069} INFO - Starting attempt 2 of 2
[2021-04-26 09:13:07,910] {taskinstance.py:1070} INFO - 
--------------------------------------------------------------------------------
[2021-04-26 09:13:08,088] {taskinstance.py:1089} INFO - Executing <Task(StageToRedshiftOperator): Stage_events> on 2020-06-01T00:00:00+00:00
[2021-04-26 09:13:08,125] {standard_task_runner.py:76} INFO - Running: ['airflow', 'tasks', 'run', 'project_dag', 'Stage_events', '2020-06-01T00:00:00+00:00', '--job-id', '47', '--pool', 'default_pool', '--raw', '--subdir', 'DAGS_FOLDER/udac_example_dag.py', '--cfg-path', '/tmp/tmpmt02o83s', '--error-file', '/tmp/tmp44oznelg']
[2021-04-26 09:13:08,127] {standard_task_runner.py:77} INFO - Job 47: Subtask Stage_events
[2021-04-26 09:13:08,112] {standard_task_runner.py:52} INFO - Started process 134 to run task
[2021-04-26 09:13:08,573] {logging_mixin.py:104} INFO - Running <TaskInstance: project_dag.Stage_events 2020-06-01T00:00:00+00:00 [running]> on host b5c40a6f08c7
[2021-04-26 09:13:08,891] {taskinstance.py:1283} INFO - Exporting the following env vars:
AIRFLOW_CTX_DAG_EMAIL=ernestoffor@gmail.com.com
AIRFLOW_CTX_DAG_OWNER=udacity
AIRFLOW_CTX_DAG_ID=project_dag
AIRFLOW_CTX_TASK_ID=Stage_events
AIRFLOW_CTX_EXECUTION_DATE=2020-06-01T00:00:00+00:00
AIRFLOW_CTX_DAG_RUN_ID=scheduled__2020-06-01T00:00:00+00:00
[2021-04-26 09:13:08,892] {stage_redshift.py:63} INFO - Start implementation of StageToRedshiftOperator
[2021-04-26 09:13:08,893] {stage_redshift.py:68} INFO - Preparing destination Redshift table
[2021-04-26 09:13:08,947] {base.py:78} INFO - Using connection to: id: redshift. Host: redshift.cxvwoeu3kuea.us-west-2.redshift.amazonaws.com, Port: 5439, Schema: dev, Login: awsuser, Password: XXXXXXXX, extra: None
[2021-04-26 09:13:10,403] {dbapi.py:180} INFO - Running statement: DELETE FROM staging_events, parameters: None
[2021-04-26 09:13:10,835] {dbapi.py:186} INFO - Rows affected: 0
[2021-04-26 09:13:11,121] {stage_redshift.py:71} INFO - Getting data from S3 to Redshift
[2021-04-26 09:13:11,259] {base.py:78} INFO - Using connection to: id: redshift. Host: redshift.cxvwoeu3kuea.us-west-2.redshift.amazonaws.com, Port: 5439, Schema: dev, Login: awsuser, Password: XXXXXXXX, extra: None
[2021-04-26 09:13:12,634] {dbapi.py:180} INFO - Running statement: 
             COPY staging_events 
             FROM 's3://udacity-dend/log_data/2018/11/*'
             FORMAT AS JSON 'log_json_path.json'
             CREDENTIALS
             'aws_access_key_id=None;aws_secret_access_key=None'
                , parameters: None
[2021-04-26 09:13:13,167] {taskinstance.py:1482} ERROR - Task failed with exception
Traceback (most recent call last):
  File "/home/airflow/.local/lib/python3.6/site-packages/airflow/models/taskinstance.py", line 1138, in _run_raw_task
    self._prepare_and_execute_task_with_callbacks(context, task)
  File "/home/airflow/.local/lib/python3.6/site-packages/airflow/models/taskinstance.py", line 1311, in _prepare_and_execute_task_with_callbacks
    result = self._execute_task(context, task_copy)
  File "/home/airflow/.local/lib/python3.6/site-packages/airflow/models/taskinstance.py", line 1341, in _execute_task
    result = task_copy.execute(context=context)
  File "/opt/airflow/plugins/operators/stage_redshift.py", line 81, in execute
    redshift.run(execution_sql)
  File "/home/airflow/.local/lib/python3.6/site-packages/airflow/hooks/dbapi.py", line 184, in run
    cur.execute(sql_statement)
psycopg2.errors.InternalError_: S3ServiceException:The AWS Access Key Id you provided does not exist in our records.,Status 403,Error InvalidAccessKeyId,Rid SWYTXTKH2Q04JXHE,ExtRid nqyGOYGUDE0rRVdhYWSGv8dcZKLvNELE3KHcpqI6MjuI4kZKeRr87GNmFkR6bO6zma97CNag5rc=,CanRetry 1
DETAIL:  
  -----------------------------------------------
  error:  S3ServiceException:The AWS Access Key Id you provided does not exist in our records.,Status 403,Error InvalidAccessKeyId,Rid SWYTXTKH2Q04JXHE,ExtRid nqyGOYGUDE0rRVdhYWSGv8dcZKLvNELE3KHcpqI6MjuI4kZKeRr87GNmFkR6bO6zma97CNag5rc=,CanRetry 1
  code:      8001
  context:   Listing bucket=udacity-dend prefix=log_data/2018/11/*
  query:     313
  location:  s3_utility.cpp:654
  process:   padbmaster [pid=14144]
  -----------------------------------------------


[2021-04-26 09:13:13,171] {taskinstance.py:1532} INFO - Marking task as FAILED. dag_id=project_dag, task_id=Stage_events, execution_date=20200601T000000, start_date=20210426T091307, end_date=20210426T091313
[2021-04-26 09:13:13,459] {local_task_job.py:146} INFO - Task exited with return code 1
[2021-04-26 12:40:07,005] {taskinstance.py:877} INFO - Dependencies all met for <TaskInstance: project_dag.Stage_events 2020-06-01T00:00:00+00:00 [queued]>
[2021-04-26 12:40:07,112] {taskinstance.py:877} INFO - Dependencies all met for <TaskInstance: project_dag.Stage_events 2020-06-01T00:00:00+00:00 [queued]>
[2021-04-26 12:40:07,112] {taskinstance.py:1068} INFO - 
--------------------------------------------------------------------------------
[2021-04-26 12:40:07,112] {taskinstance.py:1069} INFO - Starting attempt 2 of 2
[2021-04-26 12:40:07,112] {taskinstance.py:1070} INFO - 
--------------------------------------------------------------------------------
[2021-04-26 12:40:07,150] {taskinstance.py:1089} INFO - Executing <Task(StageToRedshiftOperator): Stage_events> on 2020-06-01T00:00:00+00:00
[2021-04-26 12:40:07,192] {standard_task_runner.py:76} INFO - Running: ['airflow', 'tasks', 'run', 'project_dag', 'Stage_events', '2020-06-01T00:00:00+00:00', '--job-id', '41', '--pool', 'default_pool', '--raw', '--subdir', 'DAGS_FOLDER/udac_example_dag.py', '--cfg-path', '/tmp/tmpf06q6_ya', '--error-file', '/tmp/tmp4n92kbox']
[2021-04-26 12:40:07,195] {standard_task_runner.py:77} INFO - Job 41: Subtask Stage_events
[2021-04-26 12:40:07,176] {standard_task_runner.py:52} INFO - Started process 132 to run task
[2021-04-26 12:40:07,481] {logging_mixin.py:104} INFO - Running <TaskInstance: project_dag.Stage_events 2020-06-01T00:00:00+00:00 [running]> on host 0f1e1da1f4f6
[2021-04-26 12:40:08,024] {taskinstance.py:1283} INFO - Exporting the following env vars:
AIRFLOW_CTX_DAG_EMAIL=ernestoffor@gmail.com.com
AIRFLOW_CTX_DAG_OWNER=udacity
AIRFLOW_CTX_DAG_ID=project_dag
AIRFLOW_CTX_TASK_ID=Stage_events
AIRFLOW_CTX_EXECUTION_DATE=2020-06-01T00:00:00+00:00
AIRFLOW_CTX_DAG_RUN_ID=scheduled__2020-06-01T00:00:00+00:00
[2021-04-26 12:40:08,026] {stage_redshift.py:62} INFO - Start implementation of StageToRedshiftOperator
[2021-04-26 12:40:08,026] {stage_redshift.py:67} INFO - Preparing destination Redshift table
[2021-04-26 12:40:08,077] {base.py:78} INFO - Using connection to: id: redshift. Host: redshift.cxvwoeu3kuea.us-west-2.redshift.amazonaws.com, Port: 5439, Schema: dev, Login: awsuser, Password: XXXXXXXX, extra: None
[2021-04-26 12:40:08,096] {taskinstance.py:1482} ERROR - Task failed with exception
Traceback (most recent call last):
  File "/home/airflow/.local/lib/python3.6/site-packages/airflow/models/taskinstance.py", line 1138, in _run_raw_task
    self._prepare_and_execute_task_with_callbacks(context, task)
  File "/home/airflow/.local/lib/python3.6/site-packages/airflow/models/taskinstance.py", line 1311, in _prepare_and_execute_task_with_callbacks
    result = self._execute_task(context, task_copy)
  File "/home/airflow/.local/lib/python3.6/site-packages/airflow/models/taskinstance.py", line 1341, in _execute_task
    result = task_copy.execute(context=context)
  File "/opt/airflow/plugins/operators/stage_redshift.py", line 68, in execute
    redshift.run("DELETE FROM {}".format(self.staging_table))
  File "/home/airflow/.local/lib/python3.6/site-packages/airflow/hooks/dbapi.py", line 173, in run
    with closing(self.get_conn()) as conn:
  File "/home/airflow/.local/lib/python3.6/site-packages/airflow/providers/postgres/hooks/postgres.py", line 108, in get_conn
    self.conn = psycopg2.connect(**conn_args)
  File "/home/airflow/.local/lib/python3.6/site-packages/psycopg2/__init__.py", line 127, in connect
    conn = _connect(dsn, connection_factory=connection_factory, **kwasync)
psycopg2.OperationalError: could not translate host name "redshift.cxvwoeu3kuea.us-west-2.redshift.amazonaws.com" to address: Name or service not known

[2021-04-26 12:40:08,107] {taskinstance.py:1532} INFO - Marking task as FAILED. dag_id=project_dag, task_id=Stage_events, execution_date=20200601T000000, start_date=20210426T124007, end_date=20210426T124008
[2021-04-26 12:40:08,406] {local_task_job.py:146} INFO - Task exited with return code 1
